{"num_games": 100, "student_agent_wins": [0, 1, 0, 0, 1, 1, 0, 0, 0, 1, 1, 0, 0, 0, 0, 0, 0, 0, 1, 1, 0, 0, 0, 0, 1, 1, 0, 0, 0, 0, 1, 1, 0, 0, 0, 0, 0, 0, 1, 0, 1, 0, 0, 0, 0, 0, 0, 0, 0, 0, 0, 1, 1, 0, 0, 0, 0, 0, 0, 1, 1, 0, 0, 0, 0, 0, 0, 0, 0, 0, 1, 0, 0, 0, 0, 0, 0, 0, 1, 0, 0, 0, 0, 0, 0, 0, 0, 0, 0, 0, 0, 1, 0, 1, 0, 0, 0, 0, 0, 0], "random_agent_wins": [1, 0, 1, 1, 0, 0, 1, 1, 1, 0, 0, 1, 1, 1, 1, 1, 1, 1, 0, 0, 1, 1, 1, 1, 0, 0, 1, 1, 1, 1, 0, 0, 1, 1, 1, 1, 1, 1, 0, 1, 0, 1, 1, 1, 1, 1, 1, 1, 1, 1, 1, 0, 0, 1, 1, 1, 1, 1, 1, 0, 0, 1, 1, 1, 1, 1, 1, 1, 1, 1, 0, 1, 1, 1, 1, 1, 1, 1, 0, 1, 1, 1, 1, 1, 1, 1, 1, 1, 1, 1, 1, 0, 1, 0, 1, 1, 1, 1, 1, 1], "student_agent_win_count": 21, "random_agent_win_count": 79, "student_agent_win_percentage": 0.21, "random_agent_win_percentage": 0.79, "student_agent_time_taken": 0.003739790916442871, "random_agent_time_taken": 0.003126099109649658, "run_info": [{"student_agent_score": 1, "random_agent_score": 35, "student_agent_time": 0.002176523208618164, "random_agent_time": 0.0015940666198730469, "board_size": 6, "swap_players": true, "run_out": "An exception raised. The traceback is as follows:\nTraceback (most recent call last):\n  File \"/home/ml/users/ksinha4/mlp/comp424_final_project/submissions/comp424mcgill/final-project-decidophobia/world.py\", line 310, in step\n    raise ValueError(\nValueError: [INVALID:STEP] Not a valid step from [3 3] to [3 3] and put barrier at 0, with max steps = 3\n\nExecute Random Walk!\nAn exception raised. The traceback is as follows:\nTraceback (most recent call last):\n  File \"/home/ml/users/ksinha4/mlp/comp424_final_project/submissions/comp424mcgill/final-project-decidophobia/world.py\", line 310, in step\n    raise ValueError(\nValueError: [INVALID:STEP] Not a valid step from [3 3] to [3 3] and put barrier at 0, with max steps = 3\n\nExecute Random Walk!\n"}, {"student_agent_score": 63, "random_agent_score": 1, "student_agent_time": 0.0038423538208007812, "random_agent_time": 0.0028192996978759766, "board_size": 8, "swap_players": true, "run_out": "An exception raised. The traceback is as follows:\nTraceback (most recent call last):\n  File \"/home/ml/users/ksinha4/mlp/comp424_final_project/submissions/comp424mcgill/final-project-decidophobia/world.py\", line 310, in step\n    raise ValueError(\nValueError: [INVALID:STEP] Not a valid step from [5 5] to [5 5] and put barrier at 0, with max steps = 4\n\nExecute Random Walk!\nAn exception raised. The traceback is as follows:\nTraceback (most recent call last):\n  File \"/home/ml/users/ksinha4/mlp/comp424_final_project/submissions/comp424mcgill/final-project-decidophobia/world.py\", line 310, in step\n    raise ValueError(\nValueError: [INVALID:STEP] Not a valid step from [5 4] to [5 4] and put barrier at 0, with max steps = 4\n\nExecute Random Walk!\nAn exception raised. The traceback is as follows:\nTraceback (most recent call last):\n  File \"/home/ml/users/ksinha4/mlp/comp424_final_project/submissions/comp424mcgill/final-project-decidophobia/world.py\", line 310, in step\n    raise ValueError(\nValueError: [INVALID:STEP] Not a valid step from [5 4] to [5 4] and put barrier at 0, with max steps = 4\n\nExecute Random Walk!\n"}, {"student_agent_score": 1, "random_agent_score": 63, "student_agent_time": 0.0044977664947509766, "random_agent_time": 0.001882791519165039, "board_size": 8, "swap_players": false, "run_out": "An exception raised. The traceback is as follows:\nTraceback (most recent call last):\n  File \"/home/ml/users/ksinha4/mlp/comp424_final_project/submissions/comp424mcgill/final-project-decidophobia/world.py\", line 310, in step\n    raise ValueError(\nValueError: [INVALID:STEP] Not a valid step from [2 2] to [2 2] and put barrier at 0, with max steps = 4\n\nExecute Random Walk!\nAn exception raised. The traceback is as follows:\nTraceback (most recent call last):\n  File \"/home/ml/users/ksinha4/mlp/comp424_final_project/submissions/comp424mcgill/final-project-decidophobia/world.py\", line 310, in step\n    raise ValueError(\nValueError: [INVALID:STEP] Not a valid step from [3 1] to [3 1] and put barrier at 0, with max steps = 4\n\nExecute Random Walk!\nAn exception raised. The traceback is as follows:\nTraceback (most recent call last):\n  File \"/home/ml/users/ksinha4/mlp/comp424_final_project/submissions/comp424mcgill/final-project-decidophobia/world.py\", line 310, in step\n    raise ValueError(\nValueError: [INVALID:STEP] Not a valid step from [3 0] to [3 0] and put barrier at 0, with max steps = 4\n\nExecute Random Walk!\nAn exception raised. The traceback is as follows:\nTraceback (most recent call last):\n  File \"/home/ml/users/ksinha4/mlp/comp424_final_project/submissions/comp424mcgill/final-project-decidophobia/world.py\", line 310, in step\n    raise ValueError(\nValueError: [INVALID:STEP] Not a valid step from [6 1] to [6 1] and put barrier at 0, with max steps = 4\n\nExecute Random Walk!\n"}, {"student_agent_score": 1, "random_agent_score": 35, "student_agent_time": 0.00503087043762207, "random_agent_time": 0.0008373260498046875, "board_size": 6, "swap_players": false, "run_out": "An exception raised. The traceback is as follows:\nTraceback (most recent call last):\n  File \"/home/ml/users/ksinha4/mlp/comp424_final_project/submissions/comp424mcgill/final-project-decidophobia/world.py\", line 310, in step\n    raise ValueError(\nValueError: [INVALID:STEP] Not a valid step from [2 2] to [2 2] and put barrier at 0, with max steps = 3\n\nExecute Random Walk!\nAn exception raised. The traceback is as follows:\nTraceback (most recent call last):\n  File \"/home/ml/users/ksinha4/mlp/comp424_final_project/submissions/comp424mcgill/final-project-decidophobia/world.py\", line 310, in step\n    raise ValueError(\nValueError: [INVALID:STEP] Not a valid step from [3 0] to [3 0] and put barrier at 0, with max steps = 3\n\nExecute Random Walk!\n"}, {"student_agent_score": 99, "random_agent_score": 1, "student_agent_time": 0.00025463104248046875, "random_agent_time": 0.0008151531219482422, "board_size": 10, "swap_players": true, "run_out": ""}, {"student_agent_score": 120, "random_agent_score": 1, "student_agent_time": 0.0043487548828125, "random_agent_time": 0.004662990570068359, "board_size": 11, "swap_players": true, "run_out": "An exception raised. The traceback is as follows:\nTraceback (most recent call last):\n  File \"/home/ml/users/ksinha4/mlp/comp424_final_project/submissions/comp424mcgill/final-project-decidophobia/world.py\", line 310, in step\n    raise ValueError(\nValueError: [INVALID:STEP] Not a valid step from [9 3] to [9 3] and put barrier at 0, with max steps = 6\n\nExecute Random Walk!\nAn exception raised. The traceback is as follows:\nTraceback (most recent call last):\n  File \"/home/ml/users/ksinha4/mlp/comp424_final_project/submissions/comp424mcgill/final-project-decidophobia/world.py\", line 310, in step\n    raise ValueError(\nValueError: [INVALID:STEP] Not a valid step from [9 3] to [9 3] and put barrier at 0, with max steps = 6\n\nExecute Random Walk!\n"}, {"student_agent_score": 1, "random_agent_score": 48, "student_agent_time": 0.007391214370727539, "random_agent_time": 0.0068433284759521484, "board_size": 7, "swap_players": false, "run_out": "An exception raised. The traceback is as follows:\nTraceback (most recent call last):\n  File \"/home/ml/users/ksinha4/mlp/comp424_final_project/submissions/comp424mcgill/final-project-decidophobia/world.py\", line 310, in step\n    raise ValueError(\nValueError: [INVALID:STEP] Not a valid step from [4 3] to [4 3] and put barrier at 0, with max steps = 4\n\nExecute Random Walk!\nAn exception raised. The traceback is as follows:\nTraceback (most recent call last):\n  File \"/home/ml/users/ksinha4/mlp/comp424_final_project/submissions/comp424mcgill/final-project-decidophobia/world.py\", line 310, in step\n    raise ValueError(\nValueError: [INVALID:STEP] Not a valid step from [4 2] to [4 2] and put barrier at 0, with max steps = 4\n\nExecute Random Walk!\nAn exception raised. The traceback is as follows:\nTraceback (most recent call last):\n  File \"/home/ml/users/ksinha4/mlp/comp424_final_project/submissions/comp424mcgill/final-project-decidophobia/world.py\", line 310, in step\n    raise ValueError(\nValueError: [INVALID:STEP] Not a valid step from [4 3] to [4 3] and put barrier at 0, with max steps = 4\n\nExecute Random Walk!\nAn exception raised. The traceback is as follows:\nTraceback (most recent call last):\n  File \"/home/ml/users/ksinha4/mlp/comp424_final_project/submissions/comp424mcgill/final-project-decidophobia/world.py\", line 310, in step\n    raise ValueError(\nValueError: [INVALID:STEP] Not a valid step from [5 4] to [5 4] and put barrier at 0, with max steps = 4\n\nExecute Random Walk!\nAn exception raised. The traceback is as follows:\nTraceback (most recent call last):\n  File \"/home/ml/users/ksinha4/mlp/comp424_final_project/submissions/comp424mcgill/final-project-decidophobia/world.py\", line 310, in step\n    raise ValueError(\nValueError: [INVALID:STEP] Not a valid step from [6 3] to [6 3] and put barrier at 0, with max steps = 4\n\nExecute Random Walk!\n"}, {"student_agent_score": 1, "random_agent_score": 63, "student_agent_time": 0.003870248794555664, "random_agent_time": 0.003553628921508789, "board_size": 8, "swap_players": false, "run_out": "An exception raised. The traceback is as follows:\nTraceback (most recent call last):\n  File \"/home/ml/users/ksinha4/mlp/comp424_final_project/submissions/comp424mcgill/final-project-decidophobia/world.py\", line 310, in step\n    raise ValueError(\nValueError: [INVALID:STEP] Not a valid step from [2 2] to [2 2] and put barrier at 0, with max steps = 4\n\nExecute Random Walk!\nAn exception raised. The traceback is as follows:\nTraceback (most recent call last):\n  File \"/home/ml/users/ksinha4/mlp/comp424_final_project/submissions/comp424mcgill/final-project-decidophobia/world.py\", line 310, in step\n    raise ValueError(\nValueError: [INVALID:STEP] Not a valid step from [3 1] to [3 1] and put barrier at 0, with max steps = 4\n\nExecute Random Walk!\nAn exception raised. The traceback is as follows:\nTraceback (most recent call last):\n  File \"/home/ml/users/ksinha4/mlp/comp424_final_project/submissions/comp424mcgill/final-project-decidophobia/world.py\", line 310, in step\n    raise ValueError(\nValueError: [INVALID:STEP] Not a valid step from [3 0] to [3 0] and put barrier at 0, with max steps = 4\n\nExecute Random Walk!\nAn exception raised. The traceback is as follows:\nTraceback (most recent call last):\n  File \"/home/ml/users/ksinha4/mlp/comp424_final_project/submissions/comp424mcgill/final-project-decidophobia/world.py\", line 310, in step\n    raise ValueError(\nValueError: [INVALID:STEP] Not a valid step from [6 1] to [6 1] and put barrier at 0, with max steps = 4\n\nExecute Random Walk!\n"}, {"student_agent_score": 1, "random_agent_score": 48, "student_agent_time": 0.003641843795776367, "random_agent_time": 0.0033006668090820312, "board_size": 7, "swap_players": true, "run_out": "An exception raised. The traceback is as follows:\nTraceback (most recent call last):\n  File \"/home/ml/users/ksinha4/mlp/comp424_final_project/submissions/comp424mcgill/final-project-decidophobia/world.py\", line 310, in step\n    raise ValueError(\nValueError: [INVALID:STEP] Not a valid step from [2 3] to [2 3] and put barrier at 0, with max steps = 4\n\nExecute Random Walk!\nAn exception raised. The traceback is as follows:\nTraceback (most recent call last):\n  File \"/home/ml/users/ksinha4/mlp/comp424_final_project/submissions/comp424mcgill/final-project-decidophobia/world.py\", line 310, in step\n    raise ValueError(\nValueError: [INVALID:STEP] Not a valid step from [5 4] to [5 4] and put barrier at 0, with max steps = 4\n\nExecute Random Walk!\nAn exception raised. The traceback is as follows:\nTraceback (most recent call last):\n  File \"/home/ml/users/ksinha4/mlp/comp424_final_project/submissions/comp424mcgill/final-project-decidophobia/world.py\", line 310, in step\n    raise ValueError(\nValueError: [INVALID:STEP] Not a valid step from [6 3] to [6 3] and put barrier at 0, with max steps = 4\n\nExecute Random Walk!\n"}, {"student_agent_score": 80, "random_agent_score": 1, "student_agent_time": 0.00637507438659668, "random_agent_time": 0.006697416305541992, "board_size": 9, "swap_players": true, "run_out": "An exception raised. The traceback is as follows:\nTraceback (most recent call last):\n  File \"/home/ml/users/ksinha4/mlp/comp424_final_project/submissions/comp424mcgill/final-project-decidophobia/world.py\", line 310, in step\n    raise ValueError(\nValueError: [INVALID:STEP] Not a valid step from [3 4] to [3 4] and put barrier at 0, with max steps = 5\n\nExecute Random Walk!\nAn exception raised. The traceback is as follows:\nTraceback (most recent call last):\n  File \"/home/ml/users/ksinha4/mlp/comp424_final_project/submissions/comp424mcgill/final-project-decidophobia/world.py\", line 310, in step\n    raise ValueError(\nValueError: [INVALID:STEP] Not a valid step from [3 5] to [3 5] and put barrier at 0, with max steps = 5\n\nExecute Random Walk!\nAn exception raised. The traceback is as follows:\nTraceback (most recent call last):\n  File \"/home/ml/users/ksinha4/mlp/comp424_final_project/submissions/comp424mcgill/final-project-decidophobia/world.py\", line 310, in step\n    raise ValueError(\nValueError: [INVALID:STEP] Not a valid step from [3 4] to [3 4] and put barrier at 0, with max steps = 5\n\nExecute Random Walk!\nAn exception raised. The traceback is as follows:\nTraceback (most recent call last):\n  File \"/home/ml/users/ksinha4/mlp/comp424_final_project/submissions/comp424mcgill/final-project-decidophobia/world.py\", line 310, in step\n    raise ValueError(\nValueError: [INVALID:STEP] Not a valid step from [5 4] to [5 4] and put barrier at 0, with max steps = 5\n\nExecute Random Walk!\nAn exception raised. The traceback is as follows:\nTraceback (most recent call last):\n  File \"/home/ml/users/ksinha4/mlp/comp424_final_project/submissions/comp424mcgill/final-project-decidophobia/world.py\", line 310, in step\n    raise ValueError(\nValueError: [INVALID:STEP] Not a valid step from [5 5] to [5 5] and put barrier at 0, with max steps = 5\n\nExecute Random Walk!\n"}, {"student_agent_score": 120, "random_agent_score": 1, "student_agent_time": 0.0023660659790039062, "random_agent_time": 0.002781391143798828, "board_size": 11, "swap_players": true, "run_out": "An exception raised. The traceback is as follows:\nTraceback (most recent call last):\n  File \"/home/ml/users/ksinha4/mlp/comp424_final_project/submissions/comp424mcgill/final-project-decidophobia/world.py\", line 310, in step\n    raise ValueError(\nValueError: [INVALID:STEP] Not a valid step from [9 3] to [9 3] and put barrier at 0, with max steps = 6\n\nExecute Random Walk!\nAn exception raised. The traceback is as follows:\nTraceback (most recent call last):\n  File \"/home/ml/users/ksinha4/mlp/comp424_final_project/submissions/comp424mcgill/final-project-decidophobia/world.py\", line 310, in step\n    raise ValueError(\nValueError: [INVALID:STEP] Not a valid step from [9 3] to [9 3] and put barrier at 0, with max steps = 6\n\nExecute Random Walk!\n"}, {"student_agent_score": 2, "random_agent_score": 79, "student_agent_time": 0.004424333572387695, "random_agent_time": 0.002126932144165039, "board_size": 9, "swap_players": false, "run_out": "An exception raised. The traceback is as follows:\nTraceback (most recent call last):\n  File \"/home/ml/users/ksinha4/mlp/comp424_final_project/submissions/comp424mcgill/final-project-decidophobia/world.py\", line 310, in step\n    raise ValueError(\nValueError: [INVALID:STEP] Not a valid step from [5 4] to [5 4] and put barrier at 0, with max steps = 5\n\nExecute Random Walk!\nAn exception raised. The traceback is as follows:\nTraceback (most recent call last):\n  File \"/home/ml/users/ksinha4/mlp/comp424_final_project/submissions/comp424mcgill/final-project-decidophobia/world.py\", line 310, in step\n    raise ValueError(\nValueError: [INVALID:STEP] Not a valid step from [5 3] to [5 3] and put barrier at 0, with max steps = 5\n\nExecute Random Walk!\n"}, {"student_agent_score": 1, "random_agent_score": 48, "student_agent_time": 0.0034804344177246094, "random_agent_time": 0.0043146610260009766, "board_size": 7, "swap_players": true, "run_out": "An exception raised. The traceback is as follows:\nTraceback (most recent call last):\n  File \"/home/ml/users/ksinha4/mlp/comp424_final_project/submissions/comp424mcgill/final-project-decidophobia/world.py\", line 310, in step\n    raise ValueError(\nValueError: [INVALID:STEP] Not a valid step from [2 3] to [2 3] and put barrier at 0, with max steps = 4\n\nExecute Random Walk!\nAn exception raised. The traceback is as follows:\nTraceback (most recent call last):\n  File \"/home/ml/users/ksinha4/mlp/comp424_final_project/submissions/comp424mcgill/final-project-decidophobia/world.py\", line 310, in step\n    raise ValueError(\nValueError: [INVALID:STEP] Not a valid step from [5 4] to [5 4] and put barrier at 0, with max steps = 4\n\nExecute Random Walk!\nAn exception raised. The traceback is as follows:\nTraceback (most recent call last):\n  File \"/home/ml/users/ksinha4/mlp/comp424_final_project/submissions/comp424mcgill/final-project-decidophobia/world.py\", line 310, in step\n    raise ValueError(\nValueError: [INVALID:STEP] Not a valid step from [6 3] to [6 3] and put barrier at 0, with max steps = 4\n\nExecute Random Walk!\n"}, {"student_agent_score": 1, "random_agent_score": 48, "student_agent_time": 0.002232074737548828, "random_agent_time": 0.002281665802001953, "board_size": 7, "swap_players": true, "run_out": "An exception raised. The traceback is as follows:\nTraceback (most recent call last):\n  File \"/home/ml/users/ksinha4/mlp/comp424_final_project/submissions/comp424mcgill/final-project-decidophobia/world.py\", line 310, in step\n    raise ValueError(\nValueError: [INVALID:STEP] Not a valid step from [2 3] to [2 3] and put barrier at 0, with max steps = 4\n\nExecute Random Walk!\nAn exception raised. The traceback is as follows:\nTraceback (most recent call last):\n  File \"/home/ml/users/ksinha4/mlp/comp424_final_project/submissions/comp424mcgill/final-project-decidophobia/world.py\", line 310, in step\n    raise ValueError(\nValueError: [INVALID:STEP] Not a valid step from [5 4] to [5 4] and put barrier at 0, with max steps = 4\n\nExecute Random Walk!\nAn exception raised. The traceback is as follows:\nTraceback (most recent call last):\n  File \"/home/ml/users/ksinha4/mlp/comp424_final_project/submissions/comp424mcgill/final-project-decidophobia/world.py\", line 310, in step\n    raise ValueError(\nValueError: [INVALID:STEP] Not a valid step from [6 3] to [6 3] and put barrier at 0, with max steps = 4\n\nExecute Random Walk!\n"}, {"student_agent_score": 2, "random_agent_score": 79, "student_agent_time": 0.0032265186309814453, "random_agent_time": 0.002329587936401367, "board_size": 9, "swap_players": false, "run_out": "An exception raised. The traceback is as follows:\nTraceback (most recent call last):\n  File \"/home/ml/users/ksinha4/mlp/comp424_final_project/submissions/comp424mcgill/final-project-decidophobia/world.py\", line 310, in step\n    raise ValueError(\nValueError: [INVALID:STEP] Not a valid step from [5 4] to [5 4] and put barrier at 0, with max steps = 5\n\nExecute Random Walk!\nAn exception raised. The traceback is as follows:\nTraceback (most recent call last):\n  File \"/home/ml/users/ksinha4/mlp/comp424_final_project/submissions/comp424mcgill/final-project-decidophobia/world.py\", line 310, in step\n    raise ValueError(\nValueError: [INVALID:STEP] Not a valid step from [5 3] to [5 3] and put barrier at 0, with max steps = 5\n\nExecute Random Walk!\n"}, {"student_agent_score": 1, "random_agent_score": 48, "student_agent_time": 0.003956317901611328, "random_agent_time": 0.0027303695678710938, "board_size": 7, "swap_players": true, "run_out": "An exception raised. The traceback is as follows:\nTraceback (most recent call last):\n  File \"/home/ml/users/ksinha4/mlp/comp424_final_project/submissions/comp424mcgill/final-project-decidophobia/world.py\", line 310, in step\n    raise ValueError(\nValueError: [INVALID:STEP] Not a valid step from [2 3] to [2 3] and put barrier at 0, with max steps = 4\n\nExecute Random Walk!\nAn exception raised. The traceback is as follows:\nTraceback (most recent call last):\n  File \"/home/ml/users/ksinha4/mlp/comp424_final_project/submissions/comp424mcgill/final-project-decidophobia/world.py\", line 310, in step\n    raise ValueError(\nValueError: [INVALID:STEP] Not a valid step from [5 4] to [5 4] and put barrier at 0, with max steps = 4\n\nExecute Random Walk!\nAn exception raised. The traceback is as follows:\nTraceback (most recent call last):\n  File \"/home/ml/users/ksinha4/mlp/comp424_final_project/submissions/comp424mcgill/final-project-decidophobia/world.py\", line 310, in step\n    raise ValueError(\nValueError: [INVALID:STEP] Not a valid step from [6 3] to [6 3] and put barrier at 0, with max steps = 4\n\nExecute Random Walk!\n"}, {"student_agent_score": 1, "random_agent_score": 48, "student_agent_time": 0.004602193832397461, "random_agent_time": 0.0017359256744384766, "board_size": 7, "swap_players": false, "run_out": "An exception raised. The traceback is as follows:\nTraceback (most recent call last):\n  File \"/home/ml/users/ksinha4/mlp/comp424_final_project/submissions/comp424mcgill/final-project-decidophobia/world.py\", line 310, in step\n    raise ValueError(\nValueError: [INVALID:STEP] Not a valid step from [4 3] to [4 3] and put barrier at 0, with max steps = 4\n\nExecute Random Walk!\nAn exception raised. The traceback is as follows:\nTraceback (most recent call last):\n  File \"/home/ml/users/ksinha4/mlp/comp424_final_project/submissions/comp424mcgill/final-project-decidophobia/world.py\", line 310, in step\n    raise ValueError(\nValueError: [INVALID:STEP] Not a valid step from [4 2] to [4 2] and put barrier at 0, with max steps = 4\n\nExecute Random Walk!\nAn exception raised. The traceback is as follows:\nTraceback (most recent call last):\n  File \"/home/ml/users/ksinha4/mlp/comp424_final_project/submissions/comp424mcgill/final-project-decidophobia/world.py\", line 310, in step\n    raise ValueError(\nValueError: [INVALID:STEP] Not a valid step from [4 3] to [4 3] and put barrier at 0, with max steps = 4\n\nExecute Random Walk!\nAn exception raised. The traceback is as follows:\nTraceback (most recent call last):\n  File \"/home/ml/users/ksinha4/mlp/comp424_final_project/submissions/comp424mcgill/final-project-decidophobia/world.py\", line 310, in step\n    raise ValueError(\nValueError: [INVALID:STEP] Not a valid step from [5 4] to [5 4] and put barrier at 0, with max steps = 4\n\nExecute Random Walk!\nAn exception raised. The traceback is as follows:\nTraceback (most recent call last):\n  File \"/home/ml/users/ksinha4/mlp/comp424_final_project/submissions/comp424mcgill/final-project-decidophobia/world.py\", line 310, in step\n    raise ValueError(\nValueError: [INVALID:STEP] Not a valid step from [6 3] to [6 3] and put barrier at 0, with max steps = 4\n\nExecute Random Walk!\n"}, {"student_agent_score": 2, "random_agent_score": 98, "student_agent_time": 0.0036618709564208984, "random_agent_time": 0.0043697357177734375, "board_size": 10, "swap_players": false, "run_out": "An exception raised. The traceback is as follows:\nTraceback (most recent call last):\n  File \"/home/ml/users/ksinha4/mlp/comp424_final_project/submissions/comp424mcgill/final-project-decidophobia/world.py\", line 310, in step\n    raise ValueError(\nValueError: [INVALID:STEP] Not a valid step from [7 5] to [7 5] and put barrier at 0, with max steps = 5\n\nExecute Random Walk!\nAn exception raised. The traceback is as follows:\nTraceback (most recent call last):\n  File \"/home/ml/users/ksinha4/mlp/comp424_final_project/submissions/comp424mcgill/final-project-decidophobia/world.py\", line 310, in step\n    raise ValueError(\nValueError: [INVALID:STEP] Not a valid step from [6 6] to [6 6] and put barrier at 0, with max steps = 5\n\nExecute Random Walk!\nAn exception raised. The traceback is as follows:\nTraceback (most recent call last):\n  File \"/home/ml/users/ksinha4/mlp/comp424_final_project/submissions/comp424mcgill/final-project-decidophobia/world.py\", line 310, in step\n    raise ValueError(\nValueError: [INVALID:STEP] Not a valid step from [7 8] to [7 8] and put barrier at 0, with max steps = 5\n\nExecute Random Walk!\nAn exception raised. The traceback is as follows:\nTraceback (most recent call last):\n  File \"/home/ml/users/ksinha4/mlp/comp424_final_project/submissions/comp424mcgill/final-project-decidophobia/world.py\", line 310, in step\n    raise ValueError(\nValueError: [INVALID:STEP] Not a valid step from [7 8] to [7 8] and put barrier at 0, with max steps = 5\n\nExecute Random Walk!\n"}, {"student_agent_score": 99, "random_agent_score": 1, "student_agent_time": 0.0002925395965576172, "random_agent_time": 0.0013251304626464844, "board_size": 10, "swap_players": true, "run_out": ""}, {"student_agent_score": 80, "random_agent_score": 1, "student_agent_time": 0.004875898361206055, "random_agent_time": 0.006993532180786133, "board_size": 9, "swap_players": true, "run_out": "An exception raised. The traceback is as follows:\nTraceback (most recent call last):\n  File \"/home/ml/users/ksinha4/mlp/comp424_final_project/submissions/comp424mcgill/final-project-decidophobia/world.py\", line 310, in step\n    raise ValueError(\nValueError: [INVALID:STEP] Not a valid step from [3 4] to [3 4] and put barrier at 0, with max steps = 5\n\nExecute Random Walk!\nAn exception raised. The traceback is as follows:\nTraceback (most recent call last):\n  File \"/home/ml/users/ksinha4/mlp/comp424_final_project/submissions/comp424mcgill/final-project-decidophobia/world.py\", line 310, in step\n    raise ValueError(\nValueError: [INVALID:STEP] Not a valid step from [3 5] to [3 5] and put barrier at 0, with max steps = 5\n\nExecute Random Walk!\nAn exception raised. The traceback is as follows:\nTraceback (most recent call last):\n  File \"/home/ml/users/ksinha4/mlp/comp424_final_project/submissions/comp424mcgill/final-project-decidophobia/world.py\", line 310, in step\n    raise ValueError(\nValueError: [INVALID:STEP] Not a valid step from [3 4] to [3 4] and put barrier at 0, with max steps = 5\n\nExecute Random Walk!\nAn exception raised. The traceback is as follows:\nTraceback (most recent call last):\n  File \"/home/ml/users/ksinha4/mlp/comp424_final_project/submissions/comp424mcgill/final-project-decidophobia/world.py\", line 310, in step\n    raise ValueError(\nValueError: [INVALID:STEP] Not a valid step from [5 4] to [5 4] and put barrier at 0, with max steps = 5\n\nExecute Random Walk!\nAn exception raised. The traceback is as follows:\nTraceback (most recent call last):\n  File \"/home/ml/users/ksinha4/mlp/comp424_final_project/submissions/comp424mcgill/final-project-decidophobia/world.py\", line 310, in step\n    raise ValueError(\nValueError: [INVALID:STEP] Not a valid step from [5 5] to [5 5] and put barrier at 0, with max steps = 5\n\nExecute Random Walk!\n"}, {"student_agent_score": 1, "random_agent_score": 48, "student_agent_time": 0.0037546157836914062, "random_agent_time": 0.0018923282623291016, "board_size": 7, "swap_players": false, "run_out": "An exception raised. The traceback is as follows:\nTraceback (most recent call last):\n  File \"/home/ml/users/ksinha4/mlp/comp424_final_project/submissions/comp424mcgill/final-project-decidophobia/world.py\", line 310, in step\n    raise ValueError(\nValueError: [INVALID:STEP] Not a valid step from [4 3] to [4 3] and put barrier at 0, with max steps = 4\n\nExecute Random Walk!\nAn exception raised. The traceback is as follows:\nTraceback (most recent call last):\n  File \"/home/ml/users/ksinha4/mlp/comp424_final_project/submissions/comp424mcgill/final-project-decidophobia/world.py\", line 310, in step\n    raise ValueError(\nValueError: [INVALID:STEP] Not a valid step from [4 2] to [4 2] and put barrier at 0, with max steps = 4\n\nExecute Random Walk!\nAn exception raised. The traceback is as follows:\nTraceback (most recent call last):\n  File \"/home/ml/users/ksinha4/mlp/comp424_final_project/submissions/comp424mcgill/final-project-decidophobia/world.py\", line 310, in step\n    raise ValueError(\nValueError: [INVALID:STEP] Not a valid step from [4 3] to [4 3] and put barrier at 0, with max steps = 4\n\nExecute Random Walk!\nAn exception raised. The traceback is as follows:\nTraceback (most recent call last):\n  File \"/home/ml/users/ksinha4/mlp/comp424_final_project/submissions/comp424mcgill/final-project-decidophobia/world.py\", line 310, in step\n    raise ValueError(\nValueError: [INVALID:STEP] Not a valid step from [5 4] to [5 4] and put barrier at 0, with max steps = 4\n\nExecute Random Walk!\nAn exception raised. The traceback is as follows:\nTraceback (most recent call last):\n  File \"/home/ml/users/ksinha4/mlp/comp424_final_project/submissions/comp424mcgill/final-project-decidophobia/world.py\", line 310, in step\n    raise ValueError(\nValueError: [INVALID:STEP] Not a valid step from [6 3] to [6 3] and put barrier at 0, with max steps = 4\n\nExecute Random Walk!\n"}, {"student_agent_score": 1, "random_agent_score": 48, "student_agent_time": 0.0027327537536621094, "random_agent_time": 0.0019905567169189453, "board_size": 7, "swap_players": true, "run_out": "An exception raised. The traceback is as follows:\nTraceback (most recent call last):\n  File \"/home/ml/users/ksinha4/mlp/comp424_final_project/submissions/comp424mcgill/final-project-decidophobia/world.py\", line 310, in step\n    raise ValueError(\nValueError: [INVALID:STEP] Not a valid step from [2 3] to [2 3] and put barrier at 0, with max steps = 4\n\nExecute Random Walk!\nAn exception raised. The traceback is as follows:\nTraceback (most recent call last):\n  File \"/home/ml/users/ksinha4/mlp/comp424_final_project/submissions/comp424mcgill/final-project-decidophobia/world.py\", line 310, in step\n    raise ValueError(\nValueError: [INVALID:STEP] Not a valid step from [5 4] to [5 4] and put barrier at 0, with max steps = 4\n\nExecute Random Walk!\nAn exception raised. The traceback is as follows:\nTraceback (most recent call last):\n  File \"/home/ml/users/ksinha4/mlp/comp424_final_project/submissions/comp424mcgill/final-project-decidophobia/world.py\", line 310, in step\n    raise ValueError(\nValueError: [INVALID:STEP] Not a valid step from [6 3] to [6 3] and put barrier at 0, with max steps = 4\n\nExecute Random Walk!\n"}, {"student_agent_score": 2, "random_agent_score": 98, "student_agent_time": 0.005422830581665039, "random_agent_time": 0.006500720977783203, "board_size": 10, "swap_players": false, "run_out": "An exception raised. The traceback is as follows:\nTraceback (most recent call last):\n  File \"/home/ml/users/ksinha4/mlp/comp424_final_project/submissions/comp424mcgill/final-project-decidophobia/world.py\", line 310, in step\n    raise ValueError(\nValueError: [INVALID:STEP] Not a valid step from [7 5] to [7 5] and put barrier at 0, with max steps = 5\n\nExecute Random Walk!\nAn exception raised. The traceback is as follows:\nTraceback (most recent call last):\n  File \"/home/ml/users/ksinha4/mlp/comp424_final_project/submissions/comp424mcgill/final-project-decidophobia/world.py\", line 310, in step\n    raise ValueError(\nValueError: [INVALID:STEP] Not a valid step from [6 6] to [6 6] and put barrier at 0, with max steps = 5\n\nExecute Random Walk!\nAn exception raised. The traceback is as follows:\nTraceback (most recent call last):\n  File \"/home/ml/users/ksinha4/mlp/comp424_final_project/submissions/comp424mcgill/final-project-decidophobia/world.py\", line 310, in step\n    raise ValueError(\nValueError: [INVALID:STEP] Not a valid step from [7 8] to [7 8] and put barrier at 0, with max steps = 5\n\nExecute Random Walk!\nAn exception raised. The traceback is as follows:\nTraceback (most recent call last):\n  File \"/home/ml/users/ksinha4/mlp/comp424_final_project/submissions/comp424mcgill/final-project-decidophobia/world.py\", line 310, in step\n    raise ValueError(\nValueError: [INVALID:STEP] Not a valid step from [7 8] to [7 8] and put barrier at 0, with max steps = 5\n\nExecute Random Walk!\n"}, {"student_agent_score": 1, "random_agent_score": 63, "student_agent_time": 0.0031044483184814453, "random_agent_time": 0.0018661022186279297, "board_size": 8, "swap_players": false, "run_out": "An exception raised. The traceback is as follows:\nTraceback (most recent call last):\n  File \"/home/ml/users/ksinha4/mlp/comp424_final_project/submissions/comp424mcgill/final-project-decidophobia/world.py\", line 310, in step\n    raise ValueError(\nValueError: [INVALID:STEP] Not a valid step from [2 2] to [2 2] and put barrier at 0, with max steps = 4\n\nExecute Random Walk!\nAn exception raised. The traceback is as follows:\nTraceback (most recent call last):\n  File \"/home/ml/users/ksinha4/mlp/comp424_final_project/submissions/comp424mcgill/final-project-decidophobia/world.py\", line 310, in step\n    raise ValueError(\nValueError: [INVALID:STEP] Not a valid step from [3 1] to [3 1] and put barrier at 0, with max steps = 4\n\nExecute Random Walk!\nAn exception raised. The traceback is as follows:\nTraceback (most recent call last):\n  File \"/home/ml/users/ksinha4/mlp/comp424_final_project/submissions/comp424mcgill/final-project-decidophobia/world.py\", line 310, in step\n    raise ValueError(\nValueError: [INVALID:STEP] Not a valid step from [3 0] to [3 0] and put barrier at 0, with max steps = 4\n\nExecute Random Walk!\nAn exception raised. The traceback is as follows:\nTraceback (most recent call last):\n  File \"/home/ml/users/ksinha4/mlp/comp424_final_project/submissions/comp424mcgill/final-project-decidophobia/world.py\", line 310, in step\n    raise ValueError(\nValueError: [INVALID:STEP] Not a valid step from [6 1] to [6 1] and put barrier at 0, with max steps = 4\n\nExecute Random Walk!\n"}, {"student_agent_score": 117, "random_agent_score": 1, "student_agent_time": 0.008892536163330078, "random_agent_time": 0.0062465667724609375, "board_size": 11, "swap_players": false, "run_out": "An exception raised. The traceback is as follows:\nTraceback (most recent call last):\n  File \"/home/ml/users/ksinha4/mlp/comp424_final_project/submissions/comp424mcgill/final-project-decidophobia/world.py\", line 310, in step\n    raise ValueError(\nValueError: [INVALID:STEP] Not a valid step from [1 7] to [1 7] and put barrier at 0, with max steps = 6\n\nExecute Random Walk!\nAn exception raised. The traceback is as follows:\nTraceback (most recent call last):\n  File \"/home/ml/users/ksinha4/mlp/comp424_final_project/submissions/comp424mcgill/final-project-decidophobia/world.py\", line 310, in step\n    raise ValueError(\nValueError: [INVALID:STEP] Not a valid step from [1 8] to [1 8] and put barrier at 0, with max steps = 6\n\nExecute Random Walk!\nAn exception raised. The traceback is as follows:\nTraceback (most recent call last):\n  File \"/home/ml/users/ksinha4/mlp/comp424_final_project/submissions/comp424mcgill/final-project-decidophobia/world.py\", line 310, in step\n    raise ValueError(\nValueError: [INVALID:STEP] Not a valid step from [1 6] to [1 6] and put barrier at 0, with max steps = 6\n\nExecute Random Walk!\nAn exception raised. The traceback is as follows:\nTraceback (most recent call last):\n  File \"/home/ml/users/ksinha4/mlp/comp424_final_project/submissions/comp424mcgill/final-project-decidophobia/world.py\", line 310, in step\n    raise ValueError(\nValueError: [INVALID:STEP] Not a valid step from [3 3] to [3 3] and put barrier at 0, with max steps = 6\n\nExecute Random Walk!\nAn exception raised. The traceback is as follows:\nTraceback (most recent call last):\n  File \"/home/ml/users/ksinha4/mlp/comp424_final_project/submissions/comp424mcgill/final-project-decidophobia/world.py\", line 310, in step\n    raise ValueError(\nValueError: [INVALID:STEP] Not a valid step from [3 4] to [3 4] and put barrier at 0, with max steps = 6\n\nExecute Random Walk!\nAn exception raised. The traceback is as follows:\nTraceback (most recent call last):\n  File \"/home/ml/users/ksinha4/mlp/comp424_final_project/submissions/comp424mcgill/final-project-decidophobia/world.py\", line 310, in step\n    raise ValueError(\nValueError: [INVALID:STEP] Not a valid step from [3 4] to [3 4] and put barrier at 0, with max steps = 6\n\nExecute Random Walk!\nAn exception raised. The traceback is as follows:\nTraceback (most recent call last):\n  File \"/home/ml/users/ksinha4/mlp/comp424_final_project/submissions/comp424mcgill/final-project-decidophobia/world.py\", line 310, in step\n    raise ValueError(\nValueError: [INVALID:STEP] Not a valid step from [4 4] to [4 4] and put barrier at 0, with max steps = 6\n\nExecute Random Walk!\nAn exception raised. The traceback is as follows:\nTraceback (most recent call last):\n  File \"/home/ml/users/ksinha4/mlp/comp424_final_project/submissions/comp424mcgill/final-project-decidophobia/world.py\", line 310, in step\n    raise ValueError(\nValueError: [INVALID:STEP] Not a valid step from [4 4] to [4 4] and put barrier at 0, with max steps = 6\n\nExecute Random Walk!\n"}, {"student_agent_score": 120, "random_agent_score": 1, "student_agent_time": 0.0020215511322021484, "random_agent_time": 0.002716541290283203, "board_size": 11, "swap_players": true, "run_out": "An exception raised. The traceback is as follows:\nTraceback (most recent call last):\n  File \"/home/ml/users/ksinha4/mlp/comp424_final_project/submissions/comp424mcgill/final-project-decidophobia/world.py\", line 310, in step\n    raise ValueError(\nValueError: [INVALID:STEP] Not a valid step from [9 3] to [9 3] and put barrier at 0, with max steps = 6\n\nExecute Random Walk!\nAn exception raised. The traceback is as follows:\nTraceback (most recent call last):\n  File \"/home/ml/users/ksinha4/mlp/comp424_final_project/submissions/comp424mcgill/final-project-decidophobia/world.py\", line 310, in step\n    raise ValueError(\nValueError: [INVALID:STEP] Not a valid step from [9 3] to [9 3] and put barrier at 0, with max steps = 6\n\nExecute Random Walk!\n"}, {"student_agent_score": 2, "random_agent_score": 79, "student_agent_time": 0.00459742546081543, "random_agent_time": 0.0018813610076904297, "board_size": 9, "swap_players": false, "run_out": "An exception raised. The traceback is as follows:\nTraceback (most recent call last):\n  File \"/home/ml/users/ksinha4/mlp/comp424_final_project/submissions/comp424mcgill/final-project-decidophobia/world.py\", line 310, in step\n    raise ValueError(\nValueError: [INVALID:STEP] Not a valid step from [5 4] to [5 4] and put barrier at 0, with max steps = 5\n\nExecute Random Walk!\nAn exception raised. The traceback is as follows:\nTraceback (most recent call last):\n  File \"/home/ml/users/ksinha4/mlp/comp424_final_project/submissions/comp424mcgill/final-project-decidophobia/world.py\", line 310, in step\n    raise ValueError(\nValueError: [INVALID:STEP] Not a valid step from [5 3] to [5 3] and put barrier at 0, with max steps = 5\n\nExecute Random Walk!\n"}, {"student_agent_score": 1, "random_agent_score": 48, "student_agent_time": 0.0037970542907714844, "random_agent_time": 0.0030243396759033203, "board_size": 7, "swap_players": true, "run_out": "An exception raised. The traceback is as follows:\nTraceback (most recent call last):\n  File \"/home/ml/users/ksinha4/mlp/comp424_final_project/submissions/comp424mcgill/final-project-decidophobia/world.py\", line 310, in step\n    raise ValueError(\nValueError: [INVALID:STEP] Not a valid step from [2 3] to [2 3] and put barrier at 0, with max steps = 4\n\nExecute Random Walk!\nAn exception raised. The traceback is as follows:\nTraceback (most recent call last):\n  File \"/home/ml/users/ksinha4/mlp/comp424_final_project/submissions/comp424mcgill/final-project-decidophobia/world.py\", line 310, in step\n    raise ValueError(\nValueError: [INVALID:STEP] Not a valid step from [5 4] to [5 4] and put barrier at 0, with max steps = 4\n\nExecute Random Walk!\nAn exception raised. The traceback is as follows:\nTraceback (most recent call last):\n  File \"/home/ml/users/ksinha4/mlp/comp424_final_project/submissions/comp424mcgill/final-project-decidophobia/world.py\", line 310, in step\n    raise ValueError(\nValueError: [INVALID:STEP] Not a valid step from [6 3] to [6 3] and put barrier at 0, with max steps = 4\n\nExecute Random Walk!\n"}, {"student_agent_score": 1, "random_agent_score": 48, "student_agent_time": 0.0041086673736572266, "random_agent_time": 0.0022153854370117188, "board_size": 7, "swap_players": false, "run_out": "An exception raised. The traceback is as follows:\nTraceback (most recent call last):\n  File \"/home/ml/users/ksinha4/mlp/comp424_final_project/submissions/comp424mcgill/final-project-decidophobia/world.py\", line 310, in step\n    raise ValueError(\nValueError: [INVALID:STEP] Not a valid step from [4 3] to [4 3] and put barrier at 0, with max steps = 4\n\nExecute Random Walk!\nAn exception raised. The traceback is as follows:\nTraceback (most recent call last):\n  File \"/home/ml/users/ksinha4/mlp/comp424_final_project/submissions/comp424mcgill/final-project-decidophobia/world.py\", line 310, in step\n    raise ValueError(\nValueError: [INVALID:STEP] Not a valid step from [4 2] to [4 2] and put barrier at 0, with max steps = 4\n\nExecute Random Walk!\nAn exception raised. The traceback is as follows:\nTraceback (most recent call last):\n  File \"/home/ml/users/ksinha4/mlp/comp424_final_project/submissions/comp424mcgill/final-project-decidophobia/world.py\", line 310, in step\n    raise ValueError(\nValueError: [INVALID:STEP] Not a valid step from [4 3] to [4 3] and put barrier at 0, with max steps = 4\n\nExecute Random Walk!\nAn exception raised. The traceback is as follows:\nTraceback (most recent call last):\n  File \"/home/ml/users/ksinha4/mlp/comp424_final_project/submissions/comp424mcgill/final-project-decidophobia/world.py\", line 310, in step\n    raise ValueError(\nValueError: [INVALID:STEP] Not a valid step from [5 4] to [5 4] and put barrier at 0, with max steps = 4\n\nExecute Random Walk!\nAn exception raised. The traceback is as follows:\nTraceback (most recent call last):\n  File \"/home/ml/users/ksinha4/mlp/comp424_final_project/submissions/comp424mcgill/final-project-decidophobia/world.py\", line 310, in step\n    raise ValueError(\nValueError: [INVALID:STEP] Not a valid step from [6 3] to [6 3] and put barrier at 0, with max steps = 4\n\nExecute Random Walk!\n"}, {"student_agent_score": 1, "random_agent_score": 35, "student_agent_time": 0.0014834403991699219, "random_agent_time": 0.0015239715576171875, "board_size": 6, "swap_players": true, "run_out": "An exception raised. The traceback is as follows:\nTraceback (most recent call last):\n  File \"/home/ml/users/ksinha4/mlp/comp424_final_project/submissions/comp424mcgill/final-project-decidophobia/world.py\", line 310, in step\n    raise ValueError(\nValueError: [INVALID:STEP] Not a valid step from [3 3] to [3 3] and put barrier at 0, with max steps = 3\n\nExecute Random Walk!\nAn exception raised. The traceback is as follows:\nTraceback (most recent call last):\n  File \"/home/ml/users/ksinha4/mlp/comp424_final_project/submissions/comp424mcgill/final-project-decidophobia/world.py\", line 310, in step\n    raise ValueError(\nValueError: [INVALID:STEP] Not a valid step from [3 3] to [3 3] and put barrier at 0, with max steps = 3\n\nExecute Random Walk!\n"}, {"student_agent_score": 99, "random_agent_score": 1, "student_agent_time": 0.0003139972686767578, "random_agent_time": 0.0007939338684082031, "board_size": 10, "swap_players": true, "run_out": ""}, {"student_agent_score": 63, "random_agent_score": 1, "student_agent_time": 0.0024569034576416016, "random_agent_time": 0.006445884704589844, "board_size": 8, "swap_players": true, "run_out": "An exception raised. The traceback is as follows:\nTraceback (most recent call last):\n  File \"/home/ml/users/ksinha4/mlp/comp424_final_project/submissions/comp424mcgill/final-project-decidophobia/world.py\", line 310, in step\n    raise ValueError(\nValueError: [INVALID:STEP] Not a valid step from [5 5] to [5 5] and put barrier at 0, with max steps = 4\n\nExecute Random Walk!\nAn exception raised. The traceback is as follows:\nTraceback (most recent call last):\n  File \"/home/ml/users/ksinha4/mlp/comp424_final_project/submissions/comp424mcgill/final-project-decidophobia/world.py\", line 310, in step\n    raise ValueError(\nValueError: [INVALID:STEP] Not a valid step from [5 4] to [5 4] and put barrier at 0, with max steps = 4\n\nExecute Random Walk!\nAn exception raised. The traceback is as follows:\nTraceback (most recent call last):\n  File \"/home/ml/users/ksinha4/mlp/comp424_final_project/submissions/comp424mcgill/final-project-decidophobia/world.py\", line 310, in step\n    raise ValueError(\nValueError: [INVALID:STEP] Not a valid step from [5 4] to [5 4] and put barrier at 0, with max steps = 4\n\nExecute Random Walk!\n"}, {"student_agent_score": 1, "random_agent_score": 35, "student_agent_time": 0.0030486583709716797, "random_agent_time": 0.00146484375, "board_size": 6, "swap_players": false, "run_out": "An exception raised. The traceback is as follows:\nTraceback (most recent call last):\n  File \"/home/ml/users/ksinha4/mlp/comp424_final_project/submissions/comp424mcgill/final-project-decidophobia/world.py\", line 310, in step\n    raise ValueError(\nValueError: [INVALID:STEP] Not a valid step from [2 2] to [2 2] and put barrier at 0, with max steps = 3\n\nExecute Random Walk!\nAn exception raised. The traceback is as follows:\nTraceback (most recent call last):\n  File \"/home/ml/users/ksinha4/mlp/comp424_final_project/submissions/comp424mcgill/final-project-decidophobia/world.py\", line 310, in step\n    raise ValueError(\nValueError: [INVALID:STEP] Not a valid step from [3 0] to [3 0] and put barrier at 0, with max steps = 3\n\nExecute Random Walk!\n"}, {"student_agent_score": 1, "random_agent_score": 48, "student_agent_time": 0.0040705204010009766, "random_agent_time": 0.0026683807373046875, "board_size": 7, "swap_players": false, "run_out": "An exception raised. The traceback is as follows:\nTraceback (most recent call last):\n  File \"/home/ml/users/ksinha4/mlp/comp424_final_project/submissions/comp424mcgill/final-project-decidophobia/world.py\", line 310, in step\n    raise ValueError(\nValueError: [INVALID:STEP] Not a valid step from [4 3] to [4 3] and put barrier at 0, with max steps = 4\n\nExecute Random Walk!\nAn exception raised. The traceback is as follows:\nTraceback (most recent call last):\n  File \"/home/ml/users/ksinha4/mlp/comp424_final_project/submissions/comp424mcgill/final-project-decidophobia/world.py\", line 310, in step\n    raise ValueError(\nValueError: [INVALID:STEP] Not a valid step from [4 2] to [4 2] and put barrier at 0, with max steps = 4\n\nExecute Random Walk!\nAn exception raised. The traceback is as follows:\nTraceback (most recent call last):\n  File \"/home/ml/users/ksinha4/mlp/comp424_final_project/submissions/comp424mcgill/final-project-decidophobia/world.py\", line 310, in step\n    raise ValueError(\nValueError: [INVALID:STEP] Not a valid step from [4 3] to [4 3] and put barrier at 0, with max steps = 4\n\nExecute Random Walk!\nAn exception raised. The traceback is as follows:\nTraceback (most recent call last):\n  File \"/home/ml/users/ksinha4/mlp/comp424_final_project/submissions/comp424mcgill/final-project-decidophobia/world.py\", line 310, in step\n    raise ValueError(\nValueError: [INVALID:STEP] Not a valid step from [5 4] to [5 4] and put barrier at 0, with max steps = 4\n\nExecute Random Walk!\nAn exception raised. The traceback is as follows:\nTraceback (most recent call last):\n  File \"/home/ml/users/ksinha4/mlp/comp424_final_project/submissions/comp424mcgill/final-project-decidophobia/world.py\", line 310, in step\n    raise ValueError(\nValueError: [INVALID:STEP] Not a valid step from [6 3] to [6 3] and put barrier at 0, with max steps = 4\n\nExecute Random Walk!\n"}, {"student_agent_score": 1, "random_agent_score": 48, "student_agent_time": 0.0027060508728027344, "random_agent_time": 0.0025446414947509766, "board_size": 7, "swap_players": true, "run_out": "An exception raised. The traceback is as follows:\nTraceback (most recent call last):\n  File \"/home/ml/users/ksinha4/mlp/comp424_final_project/submissions/comp424mcgill/final-project-decidophobia/world.py\", line 310, in step\n    raise ValueError(\nValueError: [INVALID:STEP] Not a valid step from [2 3] to [2 3] and put barrier at 0, with max steps = 4\n\nExecute Random Walk!\nAn exception raised. The traceback is as follows:\nTraceback (most recent call last):\n  File \"/home/ml/users/ksinha4/mlp/comp424_final_project/submissions/comp424mcgill/final-project-decidophobia/world.py\", line 310, in step\n    raise ValueError(\nValueError: [INVALID:STEP] Not a valid step from [5 4] to [5 4] and put barrier at 0, with max steps = 4\n\nExecute Random Walk!\nAn exception raised. The traceback is as follows:\nTraceback (most recent call last):\n  File \"/home/ml/users/ksinha4/mlp/comp424_final_project/submissions/comp424mcgill/final-project-decidophobia/world.py\", line 310, in step\n    raise ValueError(\nValueError: [INVALID:STEP] Not a valid step from [6 3] to [6 3] and put barrier at 0, with max steps = 4\n\nExecute Random Walk!\n"}, {"student_agent_score": 2, "random_agent_score": 79, "student_agent_time": 0.0032286643981933594, "random_agent_time": 0.002279996871948242, "board_size": 9, "swap_players": false, "run_out": "An exception raised. The traceback is as follows:\nTraceback (most recent call last):\n  File \"/home/ml/users/ksinha4/mlp/comp424_final_project/submissions/comp424mcgill/final-project-decidophobia/world.py\", line 310, in step\n    raise ValueError(\nValueError: [INVALID:STEP] Not a valid step from [5 4] to [5 4] and put barrier at 0, with max steps = 5\n\nExecute Random Walk!\nAn exception raised. The traceback is as follows:\nTraceback (most recent call last):\n  File \"/home/ml/users/ksinha4/mlp/comp424_final_project/submissions/comp424mcgill/final-project-decidophobia/world.py\", line 310, in step\n    raise ValueError(\nValueError: [INVALID:STEP] Not a valid step from [5 3] to [5 3] and put barrier at 0, with max steps = 5\n\nExecute Random Walk!\n"}, {"student_agent_score": 1, "random_agent_score": 48, "student_agent_time": 0.0033926963806152344, "random_agent_time": 0.0018260478973388672, "board_size": 7, "swap_players": false, "run_out": "An exception raised. The traceback is as follows:\nTraceback (most recent call last):\n  File \"/home/ml/users/ksinha4/mlp/comp424_final_project/submissions/comp424mcgill/final-project-decidophobia/world.py\", line 310, in step\n    raise ValueError(\nValueError: [INVALID:STEP] Not a valid step from [4 3] to [4 3] and put barrier at 0, with max steps = 4\n\nExecute Random Walk!\nAn exception raised. The traceback is as follows:\nTraceback (most recent call last):\n  File \"/home/ml/users/ksinha4/mlp/comp424_final_project/submissions/comp424mcgill/final-project-decidophobia/world.py\", line 310, in step\n    raise ValueError(\nValueError: [INVALID:STEP] Not a valid step from [4 2] to [4 2] and put barrier at 0, with max steps = 4\n\nExecute Random Walk!\nAn exception raised. The traceback is as follows:\nTraceback (most recent call last):\n  File \"/home/ml/users/ksinha4/mlp/comp424_final_project/submissions/comp424mcgill/final-project-decidophobia/world.py\", line 310, in step\n    raise ValueError(\nValueError: [INVALID:STEP] Not a valid step from [4 3] to [4 3] and put barrier at 0, with max steps = 4\n\nExecute Random Walk!\nAn exception raised. The traceback is as follows:\nTraceback (most recent call last):\n  File \"/home/ml/users/ksinha4/mlp/comp424_final_project/submissions/comp424mcgill/final-project-decidophobia/world.py\", line 310, in step\n    raise ValueError(\nValueError: [INVALID:STEP] Not a valid step from [5 4] to [5 4] and put barrier at 0, with max steps = 4\n\nExecute Random Walk!\nAn exception raised. The traceback is as follows:\nTraceback (most recent call last):\n  File \"/home/ml/users/ksinha4/mlp/comp424_final_project/submissions/comp424mcgill/final-project-decidophobia/world.py\", line 310, in step\n    raise ValueError(\nValueError: [INVALID:STEP] Not a valid step from [6 3] to [6 3] and put barrier at 0, with max steps = 4\n\nExecute Random Walk!\n"}, {"student_agent_score": 2, "random_agent_score": 98, "student_agent_time": 0.004626035690307617, "random_agent_time": 0.006791830062866211, "board_size": 10, "swap_players": false, "run_out": "An exception raised. The traceback is as follows:\nTraceback (most recent call last):\n  File \"/home/ml/users/ksinha4/mlp/comp424_final_project/submissions/comp424mcgill/final-project-decidophobia/world.py\", line 310, in step\n    raise ValueError(\nValueError: [INVALID:STEP] Not a valid step from [7 5] to [7 5] and put barrier at 0, with max steps = 5\n\nExecute Random Walk!\nAn exception raised. The traceback is as follows:\nTraceback (most recent call last):\n  File \"/home/ml/users/ksinha4/mlp/comp424_final_project/submissions/comp424mcgill/final-project-decidophobia/world.py\", line 310, in step\n    raise ValueError(\nValueError: [INVALID:STEP] Not a valid step from [6 6] to [6 6] and put barrier at 0, with max steps = 5\n\nExecute Random Walk!\nAn exception raised. The traceback is as follows:\nTraceback (most recent call last):\n  File \"/home/ml/users/ksinha4/mlp/comp424_final_project/submissions/comp424mcgill/final-project-decidophobia/world.py\", line 310, in step\n    raise ValueError(\nValueError: [INVALID:STEP] Not a valid step from [7 8] to [7 8] and put barrier at 0, with max steps = 5\n\nExecute Random Walk!\nAn exception raised. The traceback is as follows:\nTraceback (most recent call last):\n  File \"/home/ml/users/ksinha4/mlp/comp424_final_project/submissions/comp424mcgill/final-project-decidophobia/world.py\", line 310, in step\n    raise ValueError(\nValueError: [INVALID:STEP] Not a valid step from [7 8] to [7 8] and put barrier at 0, with max steps = 5\n\nExecute Random Walk!\n"}, {"student_agent_score": 120, "random_agent_score": 1, "student_agent_time": 0.002799510955810547, "random_agent_time": 0.002517223358154297, "board_size": 11, "swap_players": true, "run_out": "An exception raised. The traceback is as follows:\nTraceback (most recent call last):\n  File \"/home/ml/users/ksinha4/mlp/comp424_final_project/submissions/comp424mcgill/final-project-decidophobia/world.py\", line 310, in step\n    raise ValueError(\nValueError: [INVALID:STEP] Not a valid step from [9 3] to [9 3] and put barrier at 0, with max steps = 6\n\nExecute Random Walk!\nAn exception raised. The traceback is as follows:\nTraceback (most recent call last):\n  File \"/home/ml/users/ksinha4/mlp/comp424_final_project/submissions/comp424mcgill/final-project-decidophobia/world.py\", line 310, in step\n    raise ValueError(\nValueError: [INVALID:STEP] Not a valid step from [9 3] to [9 3] and put barrier at 0, with max steps = 6\n\nExecute Random Walk!\n"}, {"student_agent_score": 1, "random_agent_score": 48, "student_agent_time": 0.0031290054321289062, "random_agent_time": 0.001596212387084961, "board_size": 7, "swap_players": false, "run_out": "An exception raised. The traceback is as follows:\nTraceback (most recent call last):\n  File \"/home/ml/users/ksinha4/mlp/comp424_final_project/submissions/comp424mcgill/final-project-decidophobia/world.py\", line 310, in step\n    raise ValueError(\nValueError: [INVALID:STEP] Not a valid step from [4 3] to [4 3] and put barrier at 0, with max steps = 4\n\nExecute Random Walk!\nAn exception raised. The traceback is as follows:\nTraceback (most recent call last):\n  File \"/home/ml/users/ksinha4/mlp/comp424_final_project/submissions/comp424mcgill/final-project-decidophobia/world.py\", line 310, in step\n    raise ValueError(\nValueError: [INVALID:STEP] Not a valid step from [4 2] to [4 2] and put barrier at 0, with max steps = 4\n\nExecute Random Walk!\nAn exception raised. The traceback is as follows:\nTraceback (most recent call last):\n  File \"/home/ml/users/ksinha4/mlp/comp424_final_project/submissions/comp424mcgill/final-project-decidophobia/world.py\", line 310, in step\n    raise ValueError(\nValueError: [INVALID:STEP] Not a valid step from [4 3] to [4 3] and put barrier at 0, with max steps = 4\n\nExecute Random Walk!\nAn exception raised. The traceback is as follows:\nTraceback (most recent call last):\n  File \"/home/ml/users/ksinha4/mlp/comp424_final_project/submissions/comp424mcgill/final-project-decidophobia/world.py\", line 310, in step\n    raise ValueError(\nValueError: [INVALID:STEP] Not a valid step from [5 4] to [5 4] and put barrier at 0, with max steps = 4\n\nExecute Random Walk!\nAn exception raised. The traceback is as follows:\nTraceback (most recent call last):\n  File \"/home/ml/users/ksinha4/mlp/comp424_final_project/submissions/comp424mcgill/final-project-decidophobia/world.py\", line 310, in step\n    raise ValueError(\nValueError: [INVALID:STEP] Not a valid step from [6 3] to [6 3] and put barrier at 0, with max steps = 4\n\nExecute Random Walk!\n"}, {"student_agent_score": 63, "random_agent_score": 1, "student_agent_time": 0.0026159286499023438, "random_agent_time": 0.002460002899169922, "board_size": 8, "swap_players": true, "run_out": "An exception raised. The traceback is as follows:\nTraceback (most recent call last):\n  File \"/home/ml/users/ksinha4/mlp/comp424_final_project/submissions/comp424mcgill/final-project-decidophobia/world.py\", line 310, in step\n    raise ValueError(\nValueError: [INVALID:STEP] Not a valid step from [5 5] to [5 5] and put barrier at 0, with max steps = 4\n\nExecute Random Walk!\nAn exception raised. The traceback is as follows:\nTraceback (most recent call last):\n  File \"/home/ml/users/ksinha4/mlp/comp424_final_project/submissions/comp424mcgill/final-project-decidophobia/world.py\", line 310, in step\n    raise ValueError(\nValueError: [INVALID:STEP] Not a valid step from [5 4] to [5 4] and put barrier at 0, with max steps = 4\n\nExecute Random Walk!\nAn exception raised. The traceback is as follows:\nTraceback (most recent call last):\n  File \"/home/ml/users/ksinha4/mlp/comp424_final_project/submissions/comp424mcgill/final-project-decidophobia/world.py\", line 310, in step\n    raise ValueError(\nValueError: [INVALID:STEP] Not a valid step from [5 4] to [5 4] and put barrier at 0, with max steps = 4\n\nExecute Random Walk!\n"}, {"student_agent_score": 1, "random_agent_score": 48, "student_agent_time": 0.004380226135253906, "random_agent_time": 0.002469301223754883, "board_size": 7, "swap_players": true, "run_out": "An exception raised. The traceback is as follows:\nTraceback (most recent call last):\n  File \"/home/ml/users/ksinha4/mlp/comp424_final_project/submissions/comp424mcgill/final-project-decidophobia/world.py\", line 310, in step\n    raise ValueError(\nValueError: [INVALID:STEP] Not a valid step from [2 3] to [2 3] and put barrier at 0, with max steps = 4\n\nExecute Random Walk!\nAn exception raised. The traceback is as follows:\nTraceback (most recent call last):\n  File \"/home/ml/users/ksinha4/mlp/comp424_final_project/submissions/comp424mcgill/final-project-decidophobia/world.py\", line 310, in step\n    raise ValueError(\nValueError: [INVALID:STEP] Not a valid step from [5 4] to [5 4] and put barrier at 0, with max steps = 4\n\nExecute Random Walk!\nAn exception raised. The traceback is as follows:\nTraceback (most recent call last):\n  File \"/home/ml/users/ksinha4/mlp/comp424_final_project/submissions/comp424mcgill/final-project-decidophobia/world.py\", line 310, in step\n    raise ValueError(\nValueError: [INVALID:STEP] Not a valid step from [6 3] to [6 3] and put barrier at 0, with max steps = 4\n\nExecute Random Walk!\n"}, {"student_agent_score": 1, "random_agent_score": 48, "student_agent_time": 0.0031065940856933594, "random_agent_time": 0.005006074905395508, "board_size": 7, "swap_players": true, "run_out": "An exception raised. The traceback is as follows:\nTraceback (most recent call last):\n  File \"/home/ml/users/ksinha4/mlp/comp424_final_project/submissions/comp424mcgill/final-project-decidophobia/world.py\", line 310, in step\n    raise ValueError(\nValueError: [INVALID:STEP] Not a valid step from [2 3] to [2 3] and put barrier at 0, with max steps = 4\n\nExecute Random Walk!\nAn exception raised. The traceback is as follows:\nTraceback (most recent call last):\n  File \"/home/ml/users/ksinha4/mlp/comp424_final_project/submissions/comp424mcgill/final-project-decidophobia/world.py\", line 310, in step\n    raise ValueError(\nValueError: [INVALID:STEP] Not a valid step from [5 4] to [5 4] and put barrier at 0, with max steps = 4\n\nExecute Random Walk!\nAn exception raised. The traceback is as follows:\nTraceback (most recent call last):\n  File \"/home/ml/users/ksinha4/mlp/comp424_final_project/submissions/comp424mcgill/final-project-decidophobia/world.py\", line 310, in step\n    raise ValueError(\nValueError: [INVALID:STEP] Not a valid step from [6 3] to [6 3] and put barrier at 0, with max steps = 4\n\nExecute Random Walk!\n"}, {"student_agent_score": 1, "random_agent_score": 63, "student_agent_time": 0.004568815231323242, "random_agent_time": 0.0018308162689208984, "board_size": 8, "swap_players": false, "run_out": "An exception raised. The traceback is as follows:\nTraceback (most recent call last):\n  File \"/home/ml/users/ksinha4/mlp/comp424_final_project/submissions/comp424mcgill/final-project-decidophobia/world.py\", line 310, in step\n    raise ValueError(\nValueError: [INVALID:STEP] Not a valid step from [2 2] to [2 2] and put barrier at 0, with max steps = 4\n\nExecute Random Walk!\nAn exception raised. The traceback is as follows:\nTraceback (most recent call last):\n  File \"/home/ml/users/ksinha4/mlp/comp424_final_project/submissions/comp424mcgill/final-project-decidophobia/world.py\", line 310, in step\n    raise ValueError(\nValueError: [INVALID:STEP] Not a valid step from [3 1] to [3 1] and put barrier at 0, with max steps = 4\n\nExecute Random Walk!\nAn exception raised. The traceback is as follows:\nTraceback (most recent call last):\n  File \"/home/ml/users/ksinha4/mlp/comp424_final_project/submissions/comp424mcgill/final-project-decidophobia/world.py\", line 310, in step\n    raise ValueError(\nValueError: [INVALID:STEP] Not a valid step from [3 0] to [3 0] and put barrier at 0, with max steps = 4\n\nExecute Random Walk!\nAn exception raised. The traceback is as follows:\nTraceback (most recent call last):\n  File \"/home/ml/users/ksinha4/mlp/comp424_final_project/submissions/comp424mcgill/final-project-decidophobia/world.py\", line 310, in step\n    raise ValueError(\nValueError: [INVALID:STEP] Not a valid step from [6 1] to [6 1] and put barrier at 0, with max steps = 4\n\nExecute Random Walk!\n"}, {"student_agent_score": 1, "random_agent_score": 48, "student_agent_time": 0.0025446414947509766, "random_agent_time": 0.0018341541290283203, "board_size": 7, "swap_players": true, "run_out": "An exception raised. The traceback is as follows:\nTraceback (most recent call last):\n  File \"/home/ml/users/ksinha4/mlp/comp424_final_project/submissions/comp424mcgill/final-project-decidophobia/world.py\", line 310, in step\n    raise ValueError(\nValueError: [INVALID:STEP] Not a valid step from [2 3] to [2 3] and put barrier at 0, with max steps = 4\n\nExecute Random Walk!\nAn exception raised. The traceback is as follows:\nTraceback (most recent call last):\n  File \"/home/ml/users/ksinha4/mlp/comp424_final_project/submissions/comp424mcgill/final-project-decidophobia/world.py\", line 310, in step\n    raise ValueError(\nValueError: [INVALID:STEP] Not a valid step from [5 4] to [5 4] and put barrier at 0, with max steps = 4\n\nExecute Random Walk!\nAn exception raised. The traceback is as follows:\nTraceback (most recent call last):\n  File \"/home/ml/users/ksinha4/mlp/comp424_final_project/submissions/comp424mcgill/final-project-decidophobia/world.py\", line 310, in step\n    raise ValueError(\nValueError: [INVALID:STEP] Not a valid step from [6 3] to [6 3] and put barrier at 0, with max steps = 4\n\nExecute Random Walk!\n"}, {"student_agent_score": 2, "random_agent_score": 98, "student_agent_time": 0.0064165592193603516, "random_agent_time": 0.006812095642089844, "board_size": 10, "swap_players": false, "run_out": "An exception raised. The traceback is as follows:\nTraceback (most recent call last):\n  File \"/home/ml/users/ksinha4/mlp/comp424_final_project/submissions/comp424mcgill/final-project-decidophobia/world.py\", line 310, in step\n    raise ValueError(\nValueError: [INVALID:STEP] Not a valid step from [7 5] to [7 5] and put barrier at 0, with max steps = 5\n\nExecute Random Walk!\nAn exception raised. The traceback is as follows:\nTraceback (most recent call last):\n  File \"/home/ml/users/ksinha4/mlp/comp424_final_project/submissions/comp424mcgill/final-project-decidophobia/world.py\", line 310, in step\n    raise ValueError(\nValueError: [INVALID:STEP] Not a valid step from [6 6] to [6 6] and put barrier at 0, with max steps = 5\n\nExecute Random Walk!\nAn exception raised. The traceback is as follows:\nTraceback (most recent call last):\n  File \"/home/ml/users/ksinha4/mlp/comp424_final_project/submissions/comp424mcgill/final-project-decidophobia/world.py\", line 310, in step\n    raise ValueError(\nValueError: [INVALID:STEP] Not a valid step from [7 8] to [7 8] and put barrier at 0, with max steps = 5\n\nExecute Random Walk!\nAn exception raised. The traceback is as follows:\nTraceback (most recent call last):\n  File \"/home/ml/users/ksinha4/mlp/comp424_final_project/submissions/comp424mcgill/final-project-decidophobia/world.py\", line 310, in step\n    raise ValueError(\nValueError: [INVALID:STEP] Not a valid step from [7 8] to [7 8] and put barrier at 0, with max steps = 5\n\nExecute Random Walk!\n"}, {"student_agent_score": 1, "random_agent_score": 48, "student_agent_time": 0.0037131309509277344, "random_agent_time": 0.003325223922729492, "board_size": 7, "swap_players": true, "run_out": "An exception raised. The traceback is as follows:\nTraceback (most recent call last):\n  File \"/home/ml/users/ksinha4/mlp/comp424_final_project/submissions/comp424mcgill/final-project-decidophobia/world.py\", line 310, in step\n    raise ValueError(\nValueError: [INVALID:STEP] Not a valid step from [2 3] to [2 3] and put barrier at 0, with max steps = 4\n\nExecute Random Walk!\nAn exception raised. The traceback is as follows:\nTraceback (most recent call last):\n  File \"/home/ml/users/ksinha4/mlp/comp424_final_project/submissions/comp424mcgill/final-project-decidophobia/world.py\", line 310, in step\n    raise ValueError(\nValueError: [INVALID:STEP] Not a valid step from [5 4] to [5 4] and put barrier at 0, with max steps = 4\n\nExecute Random Walk!\nAn exception raised. The traceback is as follows:\nTraceback (most recent call last):\n  File \"/home/ml/users/ksinha4/mlp/comp424_final_project/submissions/comp424mcgill/final-project-decidophobia/world.py\", line 310, in step\n    raise ValueError(\nValueError: [INVALID:STEP] Not a valid step from [6 3] to [6 3] and put barrier at 0, with max steps = 4\n\nExecute Random Walk!\n"}, {"student_agent_score": 1, "random_agent_score": 48, "student_agent_time": 0.005101203918457031, "random_agent_time": 0.0033218860626220703, "board_size": 7, "swap_players": false, "run_out": "An exception raised. The traceback is as follows:\nTraceback (most recent call last):\n  File \"/home/ml/users/ksinha4/mlp/comp424_final_project/submissions/comp424mcgill/final-project-decidophobia/world.py\", line 310, in step\n    raise ValueError(\nValueError: [INVALID:STEP] Not a valid step from [4 3] to [4 3] and put barrier at 0, with max steps = 4\n\nExecute Random Walk!\nAn exception raised. The traceback is as follows:\nTraceback (most recent call last):\n  File \"/home/ml/users/ksinha4/mlp/comp424_final_project/submissions/comp424mcgill/final-project-decidophobia/world.py\", line 310, in step\n    raise ValueError(\nValueError: [INVALID:STEP] Not a valid step from [4 2] to [4 2] and put barrier at 0, with max steps = 4\n\nExecute Random Walk!\nAn exception raised. The traceback is as follows:\nTraceback (most recent call last):\n  File \"/home/ml/users/ksinha4/mlp/comp424_final_project/submissions/comp424mcgill/final-project-decidophobia/world.py\", line 310, in step\n    raise ValueError(\nValueError: [INVALID:STEP] Not a valid step from [4 3] to [4 3] and put barrier at 0, with max steps = 4\n\nExecute Random Walk!\nAn exception raised. The traceback is as follows:\nTraceback (most recent call last):\n  File \"/home/ml/users/ksinha4/mlp/comp424_final_project/submissions/comp424mcgill/final-project-decidophobia/world.py\", line 310, in step\n    raise ValueError(\nValueError: [INVALID:STEP] Not a valid step from [5 4] to [5 4] and put barrier at 0, with max steps = 4\n\nExecute Random Walk!\nAn exception raised. The traceback is as follows:\nTraceback (most recent call last):\n  File \"/home/ml/users/ksinha4/mlp/comp424_final_project/submissions/comp424mcgill/final-project-decidophobia/world.py\", line 310, in step\n    raise ValueError(\nValueError: [INVALID:STEP] Not a valid step from [6 3] to [6 3] and put barrier at 0, with max steps = 4\n\nExecute Random Walk!\n"}, {"student_agent_score": 2, "random_agent_score": 98, "student_agent_time": 0.004488468170166016, "random_agent_time": 0.006223201751708984, "board_size": 10, "swap_players": false, "run_out": "An exception raised. The traceback is as follows:\nTraceback (most recent call last):\n  File \"/home/ml/users/ksinha4/mlp/comp424_final_project/submissions/comp424mcgill/final-project-decidophobia/world.py\", line 310, in step\n    raise ValueError(\nValueError: [INVALID:STEP] Not a valid step from [7 5] to [7 5] and put barrier at 0, with max steps = 5\n\nExecute Random Walk!\nAn exception raised. The traceback is as follows:\nTraceback (most recent call last):\n  File \"/home/ml/users/ksinha4/mlp/comp424_final_project/submissions/comp424mcgill/final-project-decidophobia/world.py\", line 310, in step\n    raise ValueError(\nValueError: [INVALID:STEP] Not a valid step from [6 6] to [6 6] and put barrier at 0, with max steps = 5\n\nExecute Random Walk!\nAn exception raised. The traceback is as follows:\nTraceback (most recent call last):\n  File \"/home/ml/users/ksinha4/mlp/comp424_final_project/submissions/comp424mcgill/final-project-decidophobia/world.py\", line 310, in step\n    raise ValueError(\nValueError: [INVALID:STEP] Not a valid step from [7 8] to [7 8] and put barrier at 0, with max steps = 5\n\nExecute Random Walk!\nAn exception raised. The traceback is as follows:\nTraceback (most recent call last):\n  File \"/home/ml/users/ksinha4/mlp/comp424_final_project/submissions/comp424mcgill/final-project-decidophobia/world.py\", line 310, in step\n    raise ValueError(\nValueError: [INVALID:STEP] Not a valid step from [7 8] to [7 8] and put barrier at 0, with max steps = 5\n\nExecute Random Walk!\n"}, {"student_agent_score": 1, "random_agent_score": 48, "student_agent_time": 0.0029096603393554688, "random_agent_time": 0.002752065658569336, "board_size": 7, "swap_players": true, "run_out": "An exception raised. The traceback is as follows:\nTraceback (most recent call last):\n  File \"/home/ml/users/ksinha4/mlp/comp424_final_project/submissions/comp424mcgill/final-project-decidophobia/world.py\", line 310, in step\n    raise ValueError(\nValueError: [INVALID:STEP] Not a valid step from [2 3] to [2 3] and put barrier at 0, with max steps = 4\n\nExecute Random Walk!\nAn exception raised. The traceback is as follows:\nTraceback (most recent call last):\n  File \"/home/ml/users/ksinha4/mlp/comp424_final_project/submissions/comp424mcgill/final-project-decidophobia/world.py\", line 310, in step\n    raise ValueError(\nValueError: [INVALID:STEP] Not a valid step from [5 4] to [5 4] and put barrier at 0, with max steps = 4\n\nExecute Random Walk!\nAn exception raised. The traceback is as follows:\nTraceback (most recent call last):\n  File \"/home/ml/users/ksinha4/mlp/comp424_final_project/submissions/comp424mcgill/final-project-decidophobia/world.py\", line 310, in step\n    raise ValueError(\nValueError: [INVALID:STEP] Not a valid step from [6 3] to [6 3] and put barrier at 0, with max steps = 4\n\nExecute Random Walk!\n"}, {"student_agent_score": 1, "random_agent_score": 48, "student_agent_time": 0.0028371810913085938, "random_agent_time": 0.0026247501373291016, "board_size": 7, "swap_players": true, "run_out": "An exception raised. The traceback is as follows:\nTraceback (most recent call last):\n  File \"/home/ml/users/ksinha4/mlp/comp424_final_project/submissions/comp424mcgill/final-project-decidophobia/world.py\", line 310, in step\n    raise ValueError(\nValueError: [INVALID:STEP] Not a valid step from [2 3] to [2 3] and put barrier at 0, with max steps = 4\n\nExecute Random Walk!\nAn exception raised. The traceback is as follows:\nTraceback (most recent call last):\n  File \"/home/ml/users/ksinha4/mlp/comp424_final_project/submissions/comp424mcgill/final-project-decidophobia/world.py\", line 310, in step\n    raise ValueError(\nValueError: [INVALID:STEP] Not a valid step from [5 4] to [5 4] and put barrier at 0, with max steps = 4\n\nExecute Random Walk!\nAn exception raised. The traceback is as follows:\nTraceback (most recent call last):\n  File \"/home/ml/users/ksinha4/mlp/comp424_final_project/submissions/comp424mcgill/final-project-decidophobia/world.py\", line 310, in step\n    raise ValueError(\nValueError: [INVALID:STEP] Not a valid step from [6 3] to [6 3] and put barrier at 0, with max steps = 4\n\nExecute Random Walk!\n"}, {"student_agent_score": 117, "random_agent_score": 1, "student_agent_time": 0.008613348007202148, "random_agent_time": 0.007838964462280273, "board_size": 11, "swap_players": false, "run_out": "An exception raised. The traceback is as follows:\nTraceback (most recent call last):\n  File \"/home/ml/users/ksinha4/mlp/comp424_final_project/submissions/comp424mcgill/final-project-decidophobia/world.py\", line 310, in step\n    raise ValueError(\nValueError: [INVALID:STEP] Not a valid step from [1 7] to [1 7] and put barrier at 0, with max steps = 6\n\nExecute Random Walk!\nAn exception raised. The traceback is as follows:\nTraceback (most recent call last):\n  File \"/home/ml/users/ksinha4/mlp/comp424_final_project/submissions/comp424mcgill/final-project-decidophobia/world.py\", line 310, in step\n    raise ValueError(\nValueError: [INVALID:STEP] Not a valid step from [1 8] to [1 8] and put barrier at 0, with max steps = 6\n\nExecute Random Walk!\nAn exception raised. The traceback is as follows:\nTraceback (most recent call last):\n  File \"/home/ml/users/ksinha4/mlp/comp424_final_project/submissions/comp424mcgill/final-project-decidophobia/world.py\", line 310, in step\n    raise ValueError(\nValueError: [INVALID:STEP] Not a valid step from [1 6] to [1 6] and put barrier at 0, with max steps = 6\n\nExecute Random Walk!\nAn exception raised. The traceback is as follows:\nTraceback (most recent call last):\n  File \"/home/ml/users/ksinha4/mlp/comp424_final_project/submissions/comp424mcgill/final-project-decidophobia/world.py\", line 310, in step\n    raise ValueError(\nValueError: [INVALID:STEP] Not a valid step from [3 3] to [3 3] and put barrier at 0, with max steps = 6\n\nExecute Random Walk!\nAn exception raised. The traceback is as follows:\nTraceback (most recent call last):\n  File \"/home/ml/users/ksinha4/mlp/comp424_final_project/submissions/comp424mcgill/final-project-decidophobia/world.py\", line 310, in step\n    raise ValueError(\nValueError: [INVALID:STEP] Not a valid step from [3 4] to [3 4] and put barrier at 0, with max steps = 6\n\nExecute Random Walk!\nAn exception raised. The traceback is as follows:\nTraceback (most recent call last):\n  File \"/home/ml/users/ksinha4/mlp/comp424_final_project/submissions/comp424mcgill/final-project-decidophobia/world.py\", line 310, in step\n    raise ValueError(\nValueError: [INVALID:STEP] Not a valid step from [3 4] to [3 4] and put barrier at 0, with max steps = 6\n\nExecute Random Walk!\nAn exception raised. The traceback is as follows:\nTraceback (most recent call last):\n  File \"/home/ml/users/ksinha4/mlp/comp424_final_project/submissions/comp424mcgill/final-project-decidophobia/world.py\", line 310, in step\n    raise ValueError(\nValueError: [INVALID:STEP] Not a valid step from [4 4] to [4 4] and put barrier at 0, with max steps = 6\n\nExecute Random Walk!\nAn exception raised. The traceback is as follows:\nTraceback (most recent call last):\n  File \"/home/ml/users/ksinha4/mlp/comp424_final_project/submissions/comp424mcgill/final-project-decidophobia/world.py\", line 310, in step\n    raise ValueError(\nValueError: [INVALID:STEP] Not a valid step from [4 4] to [4 4] and put barrier at 0, with max steps = 6\n\nExecute Random Walk!\n"}, {"student_agent_score": 80, "random_agent_score": 1, "student_agent_time": 0.0053594112396240234, "random_agent_time": 0.006852388381958008, "board_size": 9, "swap_players": true, "run_out": "An exception raised. The traceback is as follows:\nTraceback (most recent call last):\n  File \"/home/ml/users/ksinha4/mlp/comp424_final_project/submissions/comp424mcgill/final-project-decidophobia/world.py\", line 310, in step\n    raise ValueError(\nValueError: [INVALID:STEP] Not a valid step from [3 4] to [3 4] and put barrier at 0, with max steps = 5\n\nExecute Random Walk!\nAn exception raised. The traceback is as follows:\nTraceback (most recent call last):\n  File \"/home/ml/users/ksinha4/mlp/comp424_final_project/submissions/comp424mcgill/final-project-decidophobia/world.py\", line 310, in step\n    raise ValueError(\nValueError: [INVALID:STEP] Not a valid step from [3 5] to [3 5] and put barrier at 0, with max steps = 5\n\nExecute Random Walk!\nAn exception raised. The traceback is as follows:\nTraceback (most recent call last):\n  File \"/home/ml/users/ksinha4/mlp/comp424_final_project/submissions/comp424mcgill/final-project-decidophobia/world.py\", line 310, in step\n    raise ValueError(\nValueError: [INVALID:STEP] Not a valid step from [3 4] to [3 4] and put barrier at 0, with max steps = 5\n\nExecute Random Walk!\nAn exception raised. The traceback is as follows:\nTraceback (most recent call last):\n  File \"/home/ml/users/ksinha4/mlp/comp424_final_project/submissions/comp424mcgill/final-project-decidophobia/world.py\", line 310, in step\n    raise ValueError(\nValueError: [INVALID:STEP] Not a valid step from [5 4] to [5 4] and put barrier at 0, with max steps = 5\n\nExecute Random Walk!\nAn exception raised. The traceback is as follows:\nTraceback (most recent call last):\n  File \"/home/ml/users/ksinha4/mlp/comp424_final_project/submissions/comp424mcgill/final-project-decidophobia/world.py\", line 310, in step\n    raise ValueError(\nValueError: [INVALID:STEP] Not a valid step from [5 5] to [5 5] and put barrier at 0, with max steps = 5\n\nExecute Random Walk!\n"}, {"student_agent_score": 1, "random_agent_score": 48, "student_agent_time": 0.005497455596923828, "random_agent_time": 0.0036530494689941406, "board_size": 7, "swap_players": false, "run_out": "An exception raised. The traceback is as follows:\nTraceback (most recent call last):\n  File \"/home/ml/users/ksinha4/mlp/comp424_final_project/submissions/comp424mcgill/final-project-decidophobia/world.py\", line 310, in step\n    raise ValueError(\nValueError: [INVALID:STEP] Not a valid step from [4 3] to [4 3] and put barrier at 0, with max steps = 4\n\nExecute Random Walk!\nAn exception raised. The traceback is as follows:\nTraceback (most recent call last):\n  File \"/home/ml/users/ksinha4/mlp/comp424_final_project/submissions/comp424mcgill/final-project-decidophobia/world.py\", line 310, in step\n    raise ValueError(\nValueError: [INVALID:STEP] Not a valid step from [4 2] to [4 2] and put barrier at 0, with max steps = 4\n\nExecute Random Walk!\nAn exception raised. The traceback is as follows:\nTraceback (most recent call last):\n  File \"/home/ml/users/ksinha4/mlp/comp424_final_project/submissions/comp424mcgill/final-project-decidophobia/world.py\", line 310, in step\n    raise ValueError(\nValueError: [INVALID:STEP] Not a valid step from [4 3] to [4 3] and put barrier at 0, with max steps = 4\n\nExecute Random Walk!\nAn exception raised. The traceback is as follows:\nTraceback (most recent call last):\n  File \"/home/ml/users/ksinha4/mlp/comp424_final_project/submissions/comp424mcgill/final-project-decidophobia/world.py\", line 310, in step\n    raise ValueError(\nValueError: [INVALID:STEP] Not a valid step from [5 4] to [5 4] and put barrier at 0, with max steps = 4\n\nExecute Random Walk!\nAn exception raised. The traceback is as follows:\nTraceback (most recent call last):\n  File \"/home/ml/users/ksinha4/mlp/comp424_final_project/submissions/comp424mcgill/final-project-decidophobia/world.py\", line 310, in step\n    raise ValueError(\nValueError: [INVALID:STEP] Not a valid step from [6 3] to [6 3] and put barrier at 0, with max steps = 4\n\nExecute Random Walk!\n"}, {"student_agent_score": 1, "random_agent_score": 63, "student_agent_time": 0.004743099212646484, "random_agent_time": 0.0025777816772460938, "board_size": 8, "swap_players": false, "run_out": "An exception raised. The traceback is as follows:\nTraceback (most recent call last):\n  File \"/home/ml/users/ksinha4/mlp/comp424_final_project/submissions/comp424mcgill/final-project-decidophobia/world.py\", line 310, in step\n    raise ValueError(\nValueError: [INVALID:STEP] Not a valid step from [2 2] to [2 2] and put barrier at 0, with max steps = 4\n\nExecute Random Walk!\nAn exception raised. The traceback is as follows:\nTraceback (most recent call last):\n  File \"/home/ml/users/ksinha4/mlp/comp424_final_project/submissions/comp424mcgill/final-project-decidophobia/world.py\", line 310, in step\n    raise ValueError(\nValueError: [INVALID:STEP] Not a valid step from [3 1] to [3 1] and put barrier at 0, with max steps = 4\n\nExecute Random Walk!\nAn exception raised. The traceback is as follows:\nTraceback (most recent call last):\n  File \"/home/ml/users/ksinha4/mlp/comp424_final_project/submissions/comp424mcgill/final-project-decidophobia/world.py\", line 310, in step\n    raise ValueError(\nValueError: [INVALID:STEP] Not a valid step from [3 0] to [3 0] and put barrier at 0, with max steps = 4\n\nExecute Random Walk!\nAn exception raised. The traceback is as follows:\nTraceback (most recent call last):\n  File \"/home/ml/users/ksinha4/mlp/comp424_final_project/submissions/comp424mcgill/final-project-decidophobia/world.py\", line 310, in step\n    raise ValueError(\nValueError: [INVALID:STEP] Not a valid step from [6 1] to [6 1] and put barrier at 0, with max steps = 4\n\nExecute Random Walk!\n"}, {"student_agent_score": 1, "random_agent_score": 48, "student_agent_time": 0.003439664840698242, "random_agent_time": 0.0025594234466552734, "board_size": 7, "swap_players": true, "run_out": "An exception raised. The traceback is as follows:\nTraceback (most recent call last):\n  File \"/home/ml/users/ksinha4/mlp/comp424_final_project/submissions/comp424mcgill/final-project-decidophobia/world.py\", line 310, in step\n    raise ValueError(\nValueError: [INVALID:STEP] Not a valid step from [2 3] to [2 3] and put barrier at 0, with max steps = 4\n\nExecute Random Walk!\nAn exception raised. The traceback is as follows:\nTraceback (most recent call last):\n  File \"/home/ml/users/ksinha4/mlp/comp424_final_project/submissions/comp424mcgill/final-project-decidophobia/world.py\", line 310, in step\n    raise ValueError(\nValueError: [INVALID:STEP] Not a valid step from [5 4] to [5 4] and put barrier at 0, with max steps = 4\n\nExecute Random Walk!\nAn exception raised. The traceback is as follows:\nTraceback (most recent call last):\n  File \"/home/ml/users/ksinha4/mlp/comp424_final_project/submissions/comp424mcgill/final-project-decidophobia/world.py\", line 310, in step\n    raise ValueError(\nValueError: [INVALID:STEP] Not a valid step from [6 3] to [6 3] and put barrier at 0, with max steps = 4\n\nExecute Random Walk!\n"}, {"student_agent_score": 1, "random_agent_score": 48, "student_agent_time": 0.003726959228515625, "random_agent_time": 0.0022106170654296875, "board_size": 7, "swap_players": false, "run_out": "An exception raised. The traceback is as follows:\nTraceback (most recent call last):\n  File \"/home/ml/users/ksinha4/mlp/comp424_final_project/submissions/comp424mcgill/final-project-decidophobia/world.py\", line 310, in step\n    raise ValueError(\nValueError: [INVALID:STEP] Not a valid step from [4 3] to [4 3] and put barrier at 0, with max steps = 4\n\nExecute Random Walk!\nAn exception raised. The traceback is as follows:\nTraceback (most recent call last):\n  File \"/home/ml/users/ksinha4/mlp/comp424_final_project/submissions/comp424mcgill/final-project-decidophobia/world.py\", line 310, in step\n    raise ValueError(\nValueError: [INVALID:STEP] Not a valid step from [4 2] to [4 2] and put barrier at 0, with max steps = 4\n\nExecute Random Walk!\nAn exception raised. The traceback is as follows:\nTraceback (most recent call last):\n  File \"/home/ml/users/ksinha4/mlp/comp424_final_project/submissions/comp424mcgill/final-project-decidophobia/world.py\", line 310, in step\n    raise ValueError(\nValueError: [INVALID:STEP] Not a valid step from [4 3] to [4 3] and put barrier at 0, with max steps = 4\n\nExecute Random Walk!\nAn exception raised. The traceback is as follows:\nTraceback (most recent call last):\n  File \"/home/ml/users/ksinha4/mlp/comp424_final_project/submissions/comp424mcgill/final-project-decidophobia/world.py\", line 310, in step\n    raise ValueError(\nValueError: [INVALID:STEP] Not a valid step from [5 4] to [5 4] and put barrier at 0, with max steps = 4\n\nExecute Random Walk!\nAn exception raised. The traceback is as follows:\nTraceback (most recent call last):\n  File \"/home/ml/users/ksinha4/mlp/comp424_final_project/submissions/comp424mcgill/final-project-decidophobia/world.py\", line 310, in step\n    raise ValueError(\nValueError: [INVALID:STEP] Not a valid step from [6 3] to [6 3] and put barrier at 0, with max steps = 4\n\nExecute Random Walk!\n"}, {"student_agent_score": 1, "random_agent_score": 35, "student_agent_time": 0.0021457672119140625, "random_agent_time": 0.0007026195526123047, "board_size": 6, "swap_players": false, "run_out": "An exception raised. The traceback is as follows:\nTraceback (most recent call last):\n  File \"/home/ml/users/ksinha4/mlp/comp424_final_project/submissions/comp424mcgill/final-project-decidophobia/world.py\", line 310, in step\n    raise ValueError(\nValueError: [INVALID:STEP] Not a valid step from [2 2] to [2 2] and put barrier at 0, with max steps = 3\n\nExecute Random Walk!\nAn exception raised. The traceback is as follows:\nTraceback (most recent call last):\n  File \"/home/ml/users/ksinha4/mlp/comp424_final_project/submissions/comp424mcgill/final-project-decidophobia/world.py\", line 310, in step\n    raise ValueError(\nValueError: [INVALID:STEP] Not a valid step from [3 0] to [3 0] and put barrier at 0, with max steps = 3\n\nExecute Random Walk!\n"}, {"student_agent_score": 1, "random_agent_score": 48, "student_agent_time": 0.002437114715576172, "random_agent_time": 0.00267791748046875, "board_size": 7, "swap_players": true, "run_out": "An exception raised. The traceback is as follows:\nTraceback (most recent call last):\n  File \"/home/ml/users/ksinha4/mlp/comp424_final_project/submissions/comp424mcgill/final-project-decidophobia/world.py\", line 310, in step\n    raise ValueError(\nValueError: [INVALID:STEP] Not a valid step from [2 3] to [2 3] and put barrier at 0, with max steps = 4\n\nExecute Random Walk!\nAn exception raised. The traceback is as follows:\nTraceback (most recent call last):\n  File \"/home/ml/users/ksinha4/mlp/comp424_final_project/submissions/comp424mcgill/final-project-decidophobia/world.py\", line 310, in step\n    raise ValueError(\nValueError: [INVALID:STEP] Not a valid step from [5 4] to [5 4] and put barrier at 0, with max steps = 4\n\nExecute Random Walk!\nAn exception raised. The traceback is as follows:\nTraceback (most recent call last):\n  File \"/home/ml/users/ksinha4/mlp/comp424_final_project/submissions/comp424mcgill/final-project-decidophobia/world.py\", line 310, in step\n    raise ValueError(\nValueError: [INVALID:STEP] Not a valid step from [6 3] to [6 3] and put barrier at 0, with max steps = 4\n\nExecute Random Walk!\n"}, {"student_agent_score": 99, "random_agent_score": 1, "student_agent_time": 0.0003783702850341797, "random_agent_time": 0.0009274482727050781, "board_size": 10, "swap_players": true, "run_out": ""}, {"student_agent_score": 63, "random_agent_score": 1, "student_agent_time": 0.0035550594329833984, "random_agent_time": 0.003094911575317383, "board_size": 8, "swap_players": true, "run_out": "An exception raised. The traceback is as follows:\nTraceback (most recent call last):\n  File \"/home/ml/users/ksinha4/mlp/comp424_final_project/submissions/comp424mcgill/final-project-decidophobia/world.py\", line 310, in step\n    raise ValueError(\nValueError: [INVALID:STEP] Not a valid step from [5 5] to [5 5] and put barrier at 0, with max steps = 4\n\nExecute Random Walk!\nAn exception raised. The traceback is as follows:\nTraceback (most recent call last):\n  File \"/home/ml/users/ksinha4/mlp/comp424_final_project/submissions/comp424mcgill/final-project-decidophobia/world.py\", line 310, in step\n    raise ValueError(\nValueError: [INVALID:STEP] Not a valid step from [5 4] to [5 4] and put barrier at 0, with max steps = 4\n\nExecute Random Walk!\nAn exception raised. The traceback is as follows:\nTraceback (most recent call last):\n  File \"/home/ml/users/ksinha4/mlp/comp424_final_project/submissions/comp424mcgill/final-project-decidophobia/world.py\", line 310, in step\n    raise ValueError(\nValueError: [INVALID:STEP] Not a valid step from [5 4] to [5 4] and put barrier at 0, with max steps = 4\n\nExecute Random Walk!\n"}, {"student_agent_score": 1, "random_agent_score": 48, "student_agent_time": 0.004645824432373047, "random_agent_time": 0.004431009292602539, "board_size": 7, "swap_players": false, "run_out": "An exception raised. The traceback is as follows:\nTraceback (most recent call last):\n  File \"/home/ml/users/ksinha4/mlp/comp424_final_project/submissions/comp424mcgill/final-project-decidophobia/world.py\", line 310, in step\n    raise ValueError(\nValueError: [INVALID:STEP] Not a valid step from [4 3] to [4 3] and put barrier at 0, with max steps = 4\n\nExecute Random Walk!\nAn exception raised. The traceback is as follows:\nTraceback (most recent call last):\n  File \"/home/ml/users/ksinha4/mlp/comp424_final_project/submissions/comp424mcgill/final-project-decidophobia/world.py\", line 310, in step\n    raise ValueError(\nValueError: [INVALID:STEP] Not a valid step from [4 2] to [4 2] and put barrier at 0, with max steps = 4\n\nExecute Random Walk!\nAn exception raised. The traceback is as follows:\nTraceback (most recent call last):\n  File \"/home/ml/users/ksinha4/mlp/comp424_final_project/submissions/comp424mcgill/final-project-decidophobia/world.py\", line 310, in step\n    raise ValueError(\nValueError: [INVALID:STEP] Not a valid step from [4 3] to [4 3] and put barrier at 0, with max steps = 4\n\nExecute Random Walk!\nAn exception raised. The traceback is as follows:\nTraceback (most recent call last):\n  File \"/home/ml/users/ksinha4/mlp/comp424_final_project/submissions/comp424mcgill/final-project-decidophobia/world.py\", line 310, in step\n    raise ValueError(\nValueError: [INVALID:STEP] Not a valid step from [5 4] to [5 4] and put barrier at 0, with max steps = 4\n\nExecute Random Walk!\nAn exception raised. The traceback is as follows:\nTraceback (most recent call last):\n  File \"/home/ml/users/ksinha4/mlp/comp424_final_project/submissions/comp424mcgill/final-project-decidophobia/world.py\", line 310, in step\n    raise ValueError(\nValueError: [INVALID:STEP] Not a valid step from [6 3] to [6 3] and put barrier at 0, with max steps = 4\n\nExecute Random Walk!\n"}, {"student_agent_score": 1, "random_agent_score": 48, "student_agent_time": 0.0028204917907714844, "random_agent_time": 0.0028543472290039062, "board_size": 7, "swap_players": true, "run_out": "An exception raised. The traceback is as follows:\nTraceback (most recent call last):\n  File \"/home/ml/users/ksinha4/mlp/comp424_final_project/submissions/comp424mcgill/final-project-decidophobia/world.py\", line 310, in step\n    raise ValueError(\nValueError: [INVALID:STEP] Not a valid step from [2 3] to [2 3] and put barrier at 0, with max steps = 4\n\nExecute Random Walk!\nAn exception raised. The traceback is as follows:\nTraceback (most recent call last):\n  File \"/home/ml/users/ksinha4/mlp/comp424_final_project/submissions/comp424mcgill/final-project-decidophobia/world.py\", line 310, in step\n    raise ValueError(\nValueError: [INVALID:STEP] Not a valid step from [5 4] to [5 4] and put barrier at 0, with max steps = 4\n\nExecute Random Walk!\nAn exception raised. The traceback is as follows:\nTraceback (most recent call last):\n  File \"/home/ml/users/ksinha4/mlp/comp424_final_project/submissions/comp424mcgill/final-project-decidophobia/world.py\", line 310, in step\n    raise ValueError(\nValueError: [INVALID:STEP] Not a valid step from [6 3] to [6 3] and put barrier at 0, with max steps = 4\n\nExecute Random Walk!\n"}, {"student_agent_score": 2, "random_agent_score": 98, "student_agent_time": 0.0043985843658447266, "random_agent_time": 0.0065343379974365234, "board_size": 10, "swap_players": false, "run_out": "An exception raised. The traceback is as follows:\nTraceback (most recent call last):\n  File \"/home/ml/users/ksinha4/mlp/comp424_final_project/submissions/comp424mcgill/final-project-decidophobia/world.py\", line 310, in step\n    raise ValueError(\nValueError: [INVALID:STEP] Not a valid step from [7 5] to [7 5] and put barrier at 0, with max steps = 5\n\nExecute Random Walk!\nAn exception raised. The traceback is as follows:\nTraceback (most recent call last):\n  File \"/home/ml/users/ksinha4/mlp/comp424_final_project/submissions/comp424mcgill/final-project-decidophobia/world.py\", line 310, in step\n    raise ValueError(\nValueError: [INVALID:STEP] Not a valid step from [6 6] to [6 6] and put barrier at 0, with max steps = 5\n\nExecute Random Walk!\nAn exception raised. The traceback is as follows:\nTraceback (most recent call last):\n  File \"/home/ml/users/ksinha4/mlp/comp424_final_project/submissions/comp424mcgill/final-project-decidophobia/world.py\", line 310, in step\n    raise ValueError(\nValueError: [INVALID:STEP] Not a valid step from [7 8] to [7 8] and put barrier at 0, with max steps = 5\n\nExecute Random Walk!\nAn exception raised. The traceback is as follows:\nTraceback (most recent call last):\n  File \"/home/ml/users/ksinha4/mlp/comp424_final_project/submissions/comp424mcgill/final-project-decidophobia/world.py\", line 310, in step\n    raise ValueError(\nValueError: [INVALID:STEP] Not a valid step from [7 8] to [7 8] and put barrier at 0, with max steps = 5\n\nExecute Random Walk!\n"}, {"student_agent_score": 1, "random_agent_score": 48, "student_agent_time": 0.003796815872192383, "random_agent_time": 0.0019922256469726562, "board_size": 7, "swap_players": false, "run_out": "An exception raised. The traceback is as follows:\nTraceback (most recent call last):\n  File \"/home/ml/users/ksinha4/mlp/comp424_final_project/submissions/comp424mcgill/final-project-decidophobia/world.py\", line 310, in step\n    raise ValueError(\nValueError: [INVALID:STEP] Not a valid step from [4 3] to [4 3] and put barrier at 0, with max steps = 4\n\nExecute Random Walk!\nAn exception raised. The traceback is as follows:\nTraceback (most recent call last):\n  File \"/home/ml/users/ksinha4/mlp/comp424_final_project/submissions/comp424mcgill/final-project-decidophobia/world.py\", line 310, in step\n    raise ValueError(\nValueError: [INVALID:STEP] Not a valid step from [4 2] to [4 2] and put barrier at 0, with max steps = 4\n\nExecute Random Walk!\nAn exception raised. The traceback is as follows:\nTraceback (most recent call last):\n  File \"/home/ml/users/ksinha4/mlp/comp424_final_project/submissions/comp424mcgill/final-project-decidophobia/world.py\", line 310, in step\n    raise ValueError(\nValueError: [INVALID:STEP] Not a valid step from [4 3] to [4 3] and put barrier at 0, with max steps = 4\n\nExecute Random Walk!\nAn exception raised. The traceback is as follows:\nTraceback (most recent call last):\n  File \"/home/ml/users/ksinha4/mlp/comp424_final_project/submissions/comp424mcgill/final-project-decidophobia/world.py\", line 310, in step\n    raise ValueError(\nValueError: [INVALID:STEP] Not a valid step from [5 4] to [5 4] and put barrier at 0, with max steps = 4\n\nExecute Random Walk!\nAn exception raised. The traceback is as follows:\nTraceback (most recent call last):\n  File \"/home/ml/users/ksinha4/mlp/comp424_final_project/submissions/comp424mcgill/final-project-decidophobia/world.py\", line 310, in step\n    raise ValueError(\nValueError: [INVALID:STEP] Not a valid step from [6 3] to [6 3] and put barrier at 0, with max steps = 4\n\nExecute Random Walk!\n"}, {"student_agent_score": 1, "random_agent_score": 48, "student_agent_time": 0.0027246475219726562, "random_agent_time": 0.002610921859741211, "board_size": 7, "swap_players": true, "run_out": "An exception raised. The traceback is as follows:\nTraceback (most recent call last):\n  File \"/home/ml/users/ksinha4/mlp/comp424_final_project/submissions/comp424mcgill/final-project-decidophobia/world.py\", line 310, in step\n    raise ValueError(\nValueError: [INVALID:STEP] Not a valid step from [2 3] to [2 3] and put barrier at 0, with max steps = 4\n\nExecute Random Walk!\nAn exception raised. The traceback is as follows:\nTraceback (most recent call last):\n  File \"/home/ml/users/ksinha4/mlp/comp424_final_project/submissions/comp424mcgill/final-project-decidophobia/world.py\", line 310, in step\n    raise ValueError(\nValueError: [INVALID:STEP] Not a valid step from [5 4] to [5 4] and put barrier at 0, with max steps = 4\n\nExecute Random Walk!\nAn exception raised. The traceback is as follows:\nTraceback (most recent call last):\n  File \"/home/ml/users/ksinha4/mlp/comp424_final_project/submissions/comp424mcgill/final-project-decidophobia/world.py\", line 310, in step\n    raise ValueError(\nValueError: [INVALID:STEP] Not a valid step from [6 3] to [6 3] and put barrier at 0, with max steps = 4\n\nExecute Random Walk!\n"}, {"student_agent_score": 1, "random_agent_score": 63, "student_agent_time": 0.003098011016845703, "random_agent_time": 0.002076387405395508, "board_size": 8, "swap_players": false, "run_out": "An exception raised. The traceback is as follows:\nTraceback (most recent call last):\n  File \"/home/ml/users/ksinha4/mlp/comp424_final_project/submissions/comp424mcgill/final-project-decidophobia/world.py\", line 310, in step\n    raise ValueError(\nValueError: [INVALID:STEP] Not a valid step from [2 2] to [2 2] and put barrier at 0, with max steps = 4\n\nExecute Random Walk!\nAn exception raised. The traceback is as follows:\nTraceback (most recent call last):\n  File \"/home/ml/users/ksinha4/mlp/comp424_final_project/submissions/comp424mcgill/final-project-decidophobia/world.py\", line 310, in step\n    raise ValueError(\nValueError: [INVALID:STEP] Not a valid step from [3 1] to [3 1] and put barrier at 0, with max steps = 4\n\nExecute Random Walk!\nAn exception raised. The traceback is as follows:\nTraceback (most recent call last):\n  File \"/home/ml/users/ksinha4/mlp/comp424_final_project/submissions/comp424mcgill/final-project-decidophobia/world.py\", line 310, in step\n    raise ValueError(\nValueError: [INVALID:STEP] Not a valid step from [3 0] to [3 0] and put barrier at 0, with max steps = 4\n\nExecute Random Walk!\nAn exception raised. The traceback is as follows:\nTraceback (most recent call last):\n  File \"/home/ml/users/ksinha4/mlp/comp424_final_project/submissions/comp424mcgill/final-project-decidophobia/world.py\", line 310, in step\n    raise ValueError(\nValueError: [INVALID:STEP] Not a valid step from [6 1] to [6 1] and put barrier at 0, with max steps = 4\n\nExecute Random Walk!\n"}, {"student_agent_score": 2, "random_agent_score": 79, "student_agent_time": 0.0030019283294677734, "random_agent_time": 0.0038213729858398438, "board_size": 9, "swap_players": false, "run_out": "An exception raised. The traceback is as follows:\nTraceback (most recent call last):\n  File \"/home/ml/users/ksinha4/mlp/comp424_final_project/submissions/comp424mcgill/final-project-decidophobia/world.py\", line 310, in step\n    raise ValueError(\nValueError: [INVALID:STEP] Not a valid step from [5 4] to [5 4] and put barrier at 0, with max steps = 5\n\nExecute Random Walk!\nAn exception raised. The traceback is as follows:\nTraceback (most recent call last):\n  File \"/home/ml/users/ksinha4/mlp/comp424_final_project/submissions/comp424mcgill/final-project-decidophobia/world.py\", line 310, in step\n    raise ValueError(\nValueError: [INVALID:STEP] Not a valid step from [5 3] to [5 3] and put barrier at 0, with max steps = 5\n\nExecute Random Walk!\n"}, {"student_agent_score": 1, "random_agent_score": 48, "student_agent_time": 0.0033740997314453125, "random_agent_time": 0.002311229705810547, "board_size": 7, "swap_players": true, "run_out": "An exception raised. The traceback is as follows:\nTraceback (most recent call last):\n  File \"/home/ml/users/ksinha4/mlp/comp424_final_project/submissions/comp424mcgill/final-project-decidophobia/world.py\", line 310, in step\n    raise ValueError(\nValueError: [INVALID:STEP] Not a valid step from [2 3] to [2 3] and put barrier at 0, with max steps = 4\n\nExecute Random Walk!\nAn exception raised. The traceback is as follows:\nTraceback (most recent call last):\n  File \"/home/ml/users/ksinha4/mlp/comp424_final_project/submissions/comp424mcgill/final-project-decidophobia/world.py\", line 310, in step\n    raise ValueError(\nValueError: [INVALID:STEP] Not a valid step from [5 4] to [5 4] and put barrier at 0, with max steps = 4\n\nExecute Random Walk!\nAn exception raised. The traceback is as follows:\nTraceback (most recent call last):\n  File \"/home/ml/users/ksinha4/mlp/comp424_final_project/submissions/comp424mcgill/final-project-decidophobia/world.py\", line 310, in step\n    raise ValueError(\nValueError: [INVALID:STEP] Not a valid step from [6 3] to [6 3] and put barrier at 0, with max steps = 4\n\nExecute Random Walk!\n"}, {"student_agent_score": 1, "random_agent_score": 48, "student_agent_time": 0.0024971961975097656, "random_agent_time": 0.0023937225341796875, "board_size": 7, "swap_players": true, "run_out": "An exception raised. The traceback is as follows:\nTraceback (most recent call last):\n  File \"/home/ml/users/ksinha4/mlp/comp424_final_project/submissions/comp424mcgill/final-project-decidophobia/world.py\", line 310, in step\n    raise ValueError(\nValueError: [INVALID:STEP] Not a valid step from [2 3] to [2 3] and put barrier at 0, with max steps = 4\n\nExecute Random Walk!\nAn exception raised. The traceback is as follows:\nTraceback (most recent call last):\n  File \"/home/ml/users/ksinha4/mlp/comp424_final_project/submissions/comp424mcgill/final-project-decidophobia/world.py\", line 310, in step\n    raise ValueError(\nValueError: [INVALID:STEP] Not a valid step from [5 4] to [5 4] and put barrier at 0, with max steps = 4\n\nExecute Random Walk!\nAn exception raised. The traceback is as follows:\nTraceback (most recent call last):\n  File \"/home/ml/users/ksinha4/mlp/comp424_final_project/submissions/comp424mcgill/final-project-decidophobia/world.py\", line 310, in step\n    raise ValueError(\nValueError: [INVALID:STEP] Not a valid step from [6 3] to [6 3] and put barrier at 0, with max steps = 4\n\nExecute Random Walk!\n"}, {"student_agent_score": 99, "random_agent_score": 1, "student_agent_time": 0.00028395652770996094, "random_agent_time": 0.0007846355438232422, "board_size": 10, "swap_players": true, "run_out": ""}, {"student_agent_score": 1, "random_agent_score": 48, "student_agent_time": 0.003432035446166992, "random_agent_time": 0.002625703811645508, "board_size": 7, "swap_players": true, "run_out": "An exception raised. The traceback is as follows:\nTraceback (most recent call last):\n  File \"/home/ml/users/ksinha4/mlp/comp424_final_project/submissions/comp424mcgill/final-project-decidophobia/world.py\", line 310, in step\n    raise ValueError(\nValueError: [INVALID:STEP] Not a valid step from [2 3] to [2 3] and put barrier at 0, with max steps = 4\n\nExecute Random Walk!\nAn exception raised. The traceback is as follows:\nTraceback (most recent call last):\n  File \"/home/ml/users/ksinha4/mlp/comp424_final_project/submissions/comp424mcgill/final-project-decidophobia/world.py\", line 310, in step\n    raise ValueError(\nValueError: [INVALID:STEP] Not a valid step from [5 4] to [5 4] and put barrier at 0, with max steps = 4\n\nExecute Random Walk!\nAn exception raised. The traceback is as follows:\nTraceback (most recent call last):\n  File \"/home/ml/users/ksinha4/mlp/comp424_final_project/submissions/comp424mcgill/final-project-decidophobia/world.py\", line 310, in step\n    raise ValueError(\nValueError: [INVALID:STEP] Not a valid step from [6 3] to [6 3] and put barrier at 0, with max steps = 4\n\nExecute Random Walk!\n"}, {"student_agent_score": 1, "random_agent_score": 48, "student_agent_time": 0.002505064010620117, "random_agent_time": 0.002627134323120117, "board_size": 7, "swap_players": true, "run_out": "An exception raised. The traceback is as follows:\nTraceback (most recent call last):\n  File \"/home/ml/users/ksinha4/mlp/comp424_final_project/submissions/comp424mcgill/final-project-decidophobia/world.py\", line 310, in step\n    raise ValueError(\nValueError: [INVALID:STEP] Not a valid step from [2 3] to [2 3] and put barrier at 0, with max steps = 4\n\nExecute Random Walk!\nAn exception raised. The traceback is as follows:\nTraceback (most recent call last):\n  File \"/home/ml/users/ksinha4/mlp/comp424_final_project/submissions/comp424mcgill/final-project-decidophobia/world.py\", line 310, in step\n    raise ValueError(\nValueError: [INVALID:STEP] Not a valid step from [5 4] to [5 4] and put barrier at 0, with max steps = 4\n\nExecute Random Walk!\nAn exception raised. The traceback is as follows:\nTraceback (most recent call last):\n  File \"/home/ml/users/ksinha4/mlp/comp424_final_project/submissions/comp424mcgill/final-project-decidophobia/world.py\", line 310, in step\n    raise ValueError(\nValueError: [INVALID:STEP] Not a valid step from [6 3] to [6 3] and put barrier at 0, with max steps = 4\n\nExecute Random Walk!\n"}, {"student_agent_score": 1, "random_agent_score": 63, "student_agent_time": 0.003275156021118164, "random_agent_time": 0.0020966529846191406, "board_size": 8, "swap_players": false, "run_out": "An exception raised. The traceback is as follows:\nTraceback (most recent call last):\n  File \"/home/ml/users/ksinha4/mlp/comp424_final_project/submissions/comp424mcgill/final-project-decidophobia/world.py\", line 310, in step\n    raise ValueError(\nValueError: [INVALID:STEP] Not a valid step from [2 2] to [2 2] and put barrier at 0, with max steps = 4\n\nExecute Random Walk!\nAn exception raised. The traceback is as follows:\nTraceback (most recent call last):\n  File \"/home/ml/users/ksinha4/mlp/comp424_final_project/submissions/comp424mcgill/final-project-decidophobia/world.py\", line 310, in step\n    raise ValueError(\nValueError: [INVALID:STEP] Not a valid step from [3 1] to [3 1] and put barrier at 0, with max steps = 4\n\nExecute Random Walk!\nAn exception raised. The traceback is as follows:\nTraceback (most recent call last):\n  File \"/home/ml/users/ksinha4/mlp/comp424_final_project/submissions/comp424mcgill/final-project-decidophobia/world.py\", line 310, in step\n    raise ValueError(\nValueError: [INVALID:STEP] Not a valid step from [3 0] to [3 0] and put barrier at 0, with max steps = 4\n\nExecute Random Walk!\nAn exception raised. The traceback is as follows:\nTraceback (most recent call last):\n  File \"/home/ml/users/ksinha4/mlp/comp424_final_project/submissions/comp424mcgill/final-project-decidophobia/world.py\", line 310, in step\n    raise ValueError(\nValueError: [INVALID:STEP] Not a valid step from [6 1] to [6 1] and put barrier at 0, with max steps = 4\n\nExecute Random Walk!\n"}, {"student_agent_score": 1, "random_agent_score": 48, "student_agent_time": 0.0051348209381103516, "random_agent_time": 0.002161264419555664, "board_size": 7, "swap_players": false, "run_out": "An exception raised. The traceback is as follows:\nTraceback (most recent call last):\n  File \"/home/ml/users/ksinha4/mlp/comp424_final_project/submissions/comp424mcgill/final-project-decidophobia/world.py\", line 310, in step\n    raise ValueError(\nValueError: [INVALID:STEP] Not a valid step from [4 3] to [4 3] and put barrier at 0, with max steps = 4\n\nExecute Random Walk!\nAn exception raised. The traceback is as follows:\nTraceback (most recent call last):\n  File \"/home/ml/users/ksinha4/mlp/comp424_final_project/submissions/comp424mcgill/final-project-decidophobia/world.py\", line 310, in step\n    raise ValueError(\nValueError: [INVALID:STEP] Not a valid step from [4 2] to [4 2] and put barrier at 0, with max steps = 4\n\nExecute Random Walk!\nAn exception raised. The traceback is as follows:\nTraceback (most recent call last):\n  File \"/home/ml/users/ksinha4/mlp/comp424_final_project/submissions/comp424mcgill/final-project-decidophobia/world.py\", line 310, in step\n    raise ValueError(\nValueError: [INVALID:STEP] Not a valid step from [4 3] to [4 3] and put barrier at 0, with max steps = 4\n\nExecute Random Walk!\nAn exception raised. The traceback is as follows:\nTraceback (most recent call last):\n  File \"/home/ml/users/ksinha4/mlp/comp424_final_project/submissions/comp424mcgill/final-project-decidophobia/world.py\", line 310, in step\n    raise ValueError(\nValueError: [INVALID:STEP] Not a valid step from [5 4] to [5 4] and put barrier at 0, with max steps = 4\n\nExecute Random Walk!\nAn exception raised. The traceback is as follows:\nTraceback (most recent call last):\n  File \"/home/ml/users/ksinha4/mlp/comp424_final_project/submissions/comp424mcgill/final-project-decidophobia/world.py\", line 310, in step\n    raise ValueError(\nValueError: [INVALID:STEP] Not a valid step from [6 3] to [6 3] and put barrier at 0, with max steps = 4\n\nExecute Random Walk!\n"}, {"student_agent_score": 1, "random_agent_score": 48, "student_agent_time": 0.0028221607208251953, "random_agent_time": 0.002900362014770508, "board_size": 7, "swap_players": true, "run_out": "An exception raised. The traceback is as follows:\nTraceback (most recent call last):\n  File \"/home/ml/users/ksinha4/mlp/comp424_final_project/submissions/comp424mcgill/final-project-decidophobia/world.py\", line 310, in step\n    raise ValueError(\nValueError: [INVALID:STEP] Not a valid step from [2 3] to [2 3] and put barrier at 0, with max steps = 4\n\nExecute Random Walk!\nAn exception raised. The traceback is as follows:\nTraceback (most recent call last):\n  File \"/home/ml/users/ksinha4/mlp/comp424_final_project/submissions/comp424mcgill/final-project-decidophobia/world.py\", line 310, in step\n    raise ValueError(\nValueError: [INVALID:STEP] Not a valid step from [5 4] to [5 4] and put barrier at 0, with max steps = 4\n\nExecute Random Walk!\nAn exception raised. The traceback is as follows:\nTraceback (most recent call last):\n  File \"/home/ml/users/ksinha4/mlp/comp424_final_project/submissions/comp424mcgill/final-project-decidophobia/world.py\", line 310, in step\n    raise ValueError(\nValueError: [INVALID:STEP] Not a valid step from [6 3] to [6 3] and put barrier at 0, with max steps = 4\n\nExecute Random Walk!\n"}, {"student_agent_score": 1, "random_agent_score": 48, "student_agent_time": 0.003985404968261719, "random_agent_time": 0.00189208984375, "board_size": 7, "swap_players": false, "run_out": "An exception raised. The traceback is as follows:\nTraceback (most recent call last):\n  File \"/home/ml/users/ksinha4/mlp/comp424_final_project/submissions/comp424mcgill/final-project-decidophobia/world.py\", line 310, in step\n    raise ValueError(\nValueError: [INVALID:STEP] Not a valid step from [4 3] to [4 3] and put barrier at 0, with max steps = 4\n\nExecute Random Walk!\nAn exception raised. The traceback is as follows:\nTraceback (most recent call last):\n  File \"/home/ml/users/ksinha4/mlp/comp424_final_project/submissions/comp424mcgill/final-project-decidophobia/world.py\", line 310, in step\n    raise ValueError(\nValueError: [INVALID:STEP] Not a valid step from [4 2] to [4 2] and put barrier at 0, with max steps = 4\n\nExecute Random Walk!\nAn exception raised. The traceback is as follows:\nTraceback (most recent call last):\n  File \"/home/ml/users/ksinha4/mlp/comp424_final_project/submissions/comp424mcgill/final-project-decidophobia/world.py\", line 310, in step\n    raise ValueError(\nValueError: [INVALID:STEP] Not a valid step from [4 3] to [4 3] and put barrier at 0, with max steps = 4\n\nExecute Random Walk!\nAn exception raised. The traceback is as follows:\nTraceback (most recent call last):\n  File \"/home/ml/users/ksinha4/mlp/comp424_final_project/submissions/comp424mcgill/final-project-decidophobia/world.py\", line 310, in step\n    raise ValueError(\nValueError: [INVALID:STEP] Not a valid step from [5 4] to [5 4] and put barrier at 0, with max steps = 4\n\nExecute Random Walk!\nAn exception raised. The traceback is as follows:\nTraceback (most recent call last):\n  File \"/home/ml/users/ksinha4/mlp/comp424_final_project/submissions/comp424mcgill/final-project-decidophobia/world.py\", line 310, in step\n    raise ValueError(\nValueError: [INVALID:STEP] Not a valid step from [6 3] to [6 3] and put barrier at 0, with max steps = 4\n\nExecute Random Walk!\n"}, {"student_agent_score": 1, "random_agent_score": 48, "student_agent_time": 0.006118059158325195, "random_agent_time": 0.0032396316528320312, "board_size": 7, "swap_players": false, "run_out": "An exception raised. The traceback is as follows:\nTraceback (most recent call last):\n  File \"/home/ml/users/ksinha4/mlp/comp424_final_project/submissions/comp424mcgill/final-project-decidophobia/world.py\", line 310, in step\n    raise ValueError(\nValueError: [INVALID:STEP] Not a valid step from [4 3] to [4 3] and put barrier at 0, with max steps = 4\n\nExecute Random Walk!\nAn exception raised. The traceback is as follows:\nTraceback (most recent call last):\n  File \"/home/ml/users/ksinha4/mlp/comp424_final_project/submissions/comp424mcgill/final-project-decidophobia/world.py\", line 310, in step\n    raise ValueError(\nValueError: [INVALID:STEP] Not a valid step from [4 2] to [4 2] and put barrier at 0, with max steps = 4\n\nExecute Random Walk!\nAn exception raised. The traceback is as follows:\nTraceback (most recent call last):\n  File \"/home/ml/users/ksinha4/mlp/comp424_final_project/submissions/comp424mcgill/final-project-decidophobia/world.py\", line 310, in step\n    raise ValueError(\nValueError: [INVALID:STEP] Not a valid step from [4 3] to [4 3] and put barrier at 0, with max steps = 4\n\nExecute Random Walk!\nAn exception raised. The traceback is as follows:\nTraceback (most recent call last):\n  File \"/home/ml/users/ksinha4/mlp/comp424_final_project/submissions/comp424mcgill/final-project-decidophobia/world.py\", line 310, in step\n    raise ValueError(\nValueError: [INVALID:STEP] Not a valid step from [5 4] to [5 4] and put barrier at 0, with max steps = 4\n\nExecute Random Walk!\nAn exception raised. The traceback is as follows:\nTraceback (most recent call last):\n  File \"/home/ml/users/ksinha4/mlp/comp424_final_project/submissions/comp424mcgill/final-project-decidophobia/world.py\", line 310, in step\n    raise ValueError(\nValueError: [INVALID:STEP] Not a valid step from [6 3] to [6 3] and put barrier at 0, with max steps = 4\n\nExecute Random Walk!\n"}, {"student_agent_score": 120, "random_agent_score": 1, "student_agent_time": 0.0018017292022705078, "random_agent_time": 0.0024995803833007812, "board_size": 11, "swap_players": true, "run_out": "An exception raised. The traceback is as follows:\nTraceback (most recent call last):\n  File \"/home/ml/users/ksinha4/mlp/comp424_final_project/submissions/comp424mcgill/final-project-decidophobia/world.py\", line 310, in step\n    raise ValueError(\nValueError: [INVALID:STEP] Not a valid step from [9 3] to [9 3] and put barrier at 0, with max steps = 6\n\nExecute Random Walk!\nAn exception raised. The traceback is as follows:\nTraceback (most recent call last):\n  File \"/home/ml/users/ksinha4/mlp/comp424_final_project/submissions/comp424mcgill/final-project-decidophobia/world.py\", line 310, in step\n    raise ValueError(\nValueError: [INVALID:STEP] Not a valid step from [9 3] to [9 3] and put barrier at 0, with max steps = 6\n\nExecute Random Walk!\n"}, {"student_agent_score": 1, "random_agent_score": 48, "student_agent_time": 0.0027942657470703125, "random_agent_time": 0.002726316452026367, "board_size": 7, "swap_players": true, "run_out": "An exception raised. The traceback is as follows:\nTraceback (most recent call last):\n  File \"/home/ml/users/ksinha4/mlp/comp424_final_project/submissions/comp424mcgill/final-project-decidophobia/world.py\", line 310, in step\n    raise ValueError(\nValueError: [INVALID:STEP] Not a valid step from [2 3] to [2 3] and put barrier at 0, with max steps = 4\n\nExecute Random Walk!\nAn exception raised. The traceback is as follows:\nTraceback (most recent call last):\n  File \"/home/ml/users/ksinha4/mlp/comp424_final_project/submissions/comp424mcgill/final-project-decidophobia/world.py\", line 310, in step\n    raise ValueError(\nValueError: [INVALID:STEP] Not a valid step from [5 4] to [5 4] and put barrier at 0, with max steps = 4\n\nExecute Random Walk!\nAn exception raised. The traceback is as follows:\nTraceback (most recent call last):\n  File \"/home/ml/users/ksinha4/mlp/comp424_final_project/submissions/comp424mcgill/final-project-decidophobia/world.py\", line 310, in step\n    raise ValueError(\nValueError: [INVALID:STEP] Not a valid step from [6 3] to [6 3] and put barrier at 0, with max steps = 4\n\nExecute Random Walk!\n"}, {"student_agent_score": 1, "random_agent_score": 48, "student_agent_time": 0.003951072692871094, "random_agent_time": 0.002794504165649414, "board_size": 7, "swap_players": true, "run_out": "An exception raised. The traceback is as follows:\nTraceback (most recent call last):\n  File \"/home/ml/users/ksinha4/mlp/comp424_final_project/submissions/comp424mcgill/final-project-decidophobia/world.py\", line 310, in step\n    raise ValueError(\nValueError: [INVALID:STEP] Not a valid step from [2 3] to [2 3] and put barrier at 0, with max steps = 4\n\nExecute Random Walk!\nAn exception raised. The traceback is as follows:\nTraceback (most recent call last):\n  File \"/home/ml/users/ksinha4/mlp/comp424_final_project/submissions/comp424mcgill/final-project-decidophobia/world.py\", line 310, in step\n    raise ValueError(\nValueError: [INVALID:STEP] Not a valid step from [5 4] to [5 4] and put barrier at 0, with max steps = 4\n\nExecute Random Walk!\nAn exception raised. The traceback is as follows:\nTraceback (most recent call last):\n  File \"/home/ml/users/ksinha4/mlp/comp424_final_project/submissions/comp424mcgill/final-project-decidophobia/world.py\", line 310, in step\n    raise ValueError(\nValueError: [INVALID:STEP] Not a valid step from [6 3] to [6 3] and put barrier at 0, with max steps = 4\n\nExecute Random Walk!\n"}, {"student_agent_score": 1, "random_agent_score": 48, "student_agent_time": 0.005365610122680664, "random_agent_time": 0.003175497055053711, "board_size": 7, "swap_players": false, "run_out": "An exception raised. The traceback is as follows:\nTraceback (most recent call last):\n  File \"/home/ml/users/ksinha4/mlp/comp424_final_project/submissions/comp424mcgill/final-project-decidophobia/world.py\", line 310, in step\n    raise ValueError(\nValueError: [INVALID:STEP] Not a valid step from [4 3] to [4 3] and put barrier at 0, with max steps = 4\n\nExecute Random Walk!\nAn exception raised. The traceback is as follows:\nTraceback (most recent call last):\n  File \"/home/ml/users/ksinha4/mlp/comp424_final_project/submissions/comp424mcgill/final-project-decidophobia/world.py\", line 310, in step\n    raise ValueError(\nValueError: [INVALID:STEP] Not a valid step from [4 2] to [4 2] and put barrier at 0, with max steps = 4\n\nExecute Random Walk!\nAn exception raised. The traceback is as follows:\nTraceback (most recent call last):\n  File \"/home/ml/users/ksinha4/mlp/comp424_final_project/submissions/comp424mcgill/final-project-decidophobia/world.py\", line 310, in step\n    raise ValueError(\nValueError: [INVALID:STEP] Not a valid step from [4 3] to [4 3] and put barrier at 0, with max steps = 4\n\nExecute Random Walk!\nAn exception raised. The traceback is as follows:\nTraceback (most recent call last):\n  File \"/home/ml/users/ksinha4/mlp/comp424_final_project/submissions/comp424mcgill/final-project-decidophobia/world.py\", line 310, in step\n    raise ValueError(\nValueError: [INVALID:STEP] Not a valid step from [5 4] to [5 4] and put barrier at 0, with max steps = 4\n\nExecute Random Walk!\nAn exception raised. The traceback is as follows:\nTraceback (most recent call last):\n  File \"/home/ml/users/ksinha4/mlp/comp424_final_project/submissions/comp424mcgill/final-project-decidophobia/world.py\", line 310, in step\n    raise ValueError(\nValueError: [INVALID:STEP] Not a valid step from [6 3] to [6 3] and put barrier at 0, with max steps = 4\n\nExecute Random Walk!\n"}, {"student_agent_score": 1, "random_agent_score": 48, "student_agent_time": 0.0026197433471679688, "random_agent_time": 0.0021812915802001953, "board_size": 7, "swap_players": true, "run_out": "An exception raised. The traceback is as follows:\nTraceback (most recent call last):\n  File \"/home/ml/users/ksinha4/mlp/comp424_final_project/submissions/comp424mcgill/final-project-decidophobia/world.py\", line 310, in step\n    raise ValueError(\nValueError: [INVALID:STEP] Not a valid step from [2 3] to [2 3] and put barrier at 0, with max steps = 4\n\nExecute Random Walk!\nAn exception raised. The traceback is as follows:\nTraceback (most recent call last):\n  File \"/home/ml/users/ksinha4/mlp/comp424_final_project/submissions/comp424mcgill/final-project-decidophobia/world.py\", line 310, in step\n    raise ValueError(\nValueError: [INVALID:STEP] Not a valid step from [5 4] to [5 4] and put barrier at 0, with max steps = 4\n\nExecute Random Walk!\nAn exception raised. The traceback is as follows:\nTraceback (most recent call last):\n  File \"/home/ml/users/ksinha4/mlp/comp424_final_project/submissions/comp424mcgill/final-project-decidophobia/world.py\", line 310, in step\n    raise ValueError(\nValueError: [INVALID:STEP] Not a valid step from [6 3] to [6 3] and put barrier at 0, with max steps = 4\n\nExecute Random Walk!\n"}, {"student_agent_score": 2, "random_agent_score": 98, "student_agent_time": 0.004981040954589844, "random_agent_time": 0.005980253219604492, "board_size": 10, "swap_players": false, "run_out": "An exception raised. The traceback is as follows:\nTraceback (most recent call last):\n  File \"/home/ml/users/ksinha4/mlp/comp424_final_project/submissions/comp424mcgill/final-project-decidophobia/world.py\", line 310, in step\n    raise ValueError(\nValueError: [INVALID:STEP] Not a valid step from [7 5] to [7 5] and put barrier at 0, with max steps = 5\n\nExecute Random Walk!\nAn exception raised. The traceback is as follows:\nTraceback (most recent call last):\n  File \"/home/ml/users/ksinha4/mlp/comp424_final_project/submissions/comp424mcgill/final-project-decidophobia/world.py\", line 310, in step\n    raise ValueError(\nValueError: [INVALID:STEP] Not a valid step from [6 6] to [6 6] and put barrier at 0, with max steps = 5\n\nExecute Random Walk!\nAn exception raised. The traceback is as follows:\nTraceback (most recent call last):\n  File \"/home/ml/users/ksinha4/mlp/comp424_final_project/submissions/comp424mcgill/final-project-decidophobia/world.py\", line 310, in step\n    raise ValueError(\nValueError: [INVALID:STEP] Not a valid step from [7 8] to [7 8] and put barrier at 0, with max steps = 5\n\nExecute Random Walk!\nAn exception raised. The traceback is as follows:\nTraceback (most recent call last):\n  File \"/home/ml/users/ksinha4/mlp/comp424_final_project/submissions/comp424mcgill/final-project-decidophobia/world.py\", line 310, in step\n    raise ValueError(\nValueError: [INVALID:STEP] Not a valid step from [7 8] to [7 8] and put barrier at 0, with max steps = 5\n\nExecute Random Walk!\n"}, {"student_agent_score": 1, "random_agent_score": 48, "student_agent_time": 0.004368782043457031, "random_agent_time": 0.002907991409301758, "board_size": 7, "swap_players": false, "run_out": "An exception raised. The traceback is as follows:\nTraceback (most recent call last):\n  File \"/home/ml/users/ksinha4/mlp/comp424_final_project/submissions/comp424mcgill/final-project-decidophobia/world.py\", line 310, in step\n    raise ValueError(\nValueError: [INVALID:STEP] Not a valid step from [4 3] to [4 3] and put barrier at 0, with max steps = 4\n\nExecute Random Walk!\nAn exception raised. The traceback is as follows:\nTraceback (most recent call last):\n  File \"/home/ml/users/ksinha4/mlp/comp424_final_project/submissions/comp424mcgill/final-project-decidophobia/world.py\", line 310, in step\n    raise ValueError(\nValueError: [INVALID:STEP] Not a valid step from [4 2] to [4 2] and put barrier at 0, with max steps = 4\n\nExecute Random Walk!\nAn exception raised. The traceback is as follows:\nTraceback (most recent call last):\n  File \"/home/ml/users/ksinha4/mlp/comp424_final_project/submissions/comp424mcgill/final-project-decidophobia/world.py\", line 310, in step\n    raise ValueError(\nValueError: [INVALID:STEP] Not a valid step from [4 3] to [4 3] and put barrier at 0, with max steps = 4\n\nExecute Random Walk!\nAn exception raised. The traceback is as follows:\nTraceback (most recent call last):\n  File \"/home/ml/users/ksinha4/mlp/comp424_final_project/submissions/comp424mcgill/final-project-decidophobia/world.py\", line 310, in step\n    raise ValueError(\nValueError: [INVALID:STEP] Not a valid step from [5 4] to [5 4] and put barrier at 0, with max steps = 4\n\nExecute Random Walk!\nAn exception raised. The traceback is as follows:\nTraceback (most recent call last):\n  File \"/home/ml/users/ksinha4/mlp/comp424_final_project/submissions/comp424mcgill/final-project-decidophobia/world.py\", line 310, in step\n    raise ValueError(\nValueError: [INVALID:STEP] Not a valid step from [6 3] to [6 3] and put barrier at 0, with max steps = 4\n\nExecute Random Walk!\n"}, {"student_agent_score": 1, "random_agent_score": 48, "student_agent_time": 0.004101276397705078, "random_agent_time": 0.002014636993408203, "board_size": 7, "swap_players": false, "run_out": "An exception raised. The traceback is as follows:\nTraceback (most recent call last):\n  File \"/home/ml/users/ksinha4/mlp/comp424_final_project/submissions/comp424mcgill/final-project-decidophobia/world.py\", line 310, in step\n    raise ValueError(\nValueError: [INVALID:STEP] Not a valid step from [4 3] to [4 3] and put barrier at 0, with max steps = 4\n\nExecute Random Walk!\nAn exception raised. The traceback is as follows:\nTraceback (most recent call last):\n  File \"/home/ml/users/ksinha4/mlp/comp424_final_project/submissions/comp424mcgill/final-project-decidophobia/world.py\", line 310, in step\n    raise ValueError(\nValueError: [INVALID:STEP] Not a valid step from [4 2] to [4 2] and put barrier at 0, with max steps = 4\n\nExecute Random Walk!\nAn exception raised. The traceback is as follows:\nTraceback (most recent call last):\n  File \"/home/ml/users/ksinha4/mlp/comp424_final_project/submissions/comp424mcgill/final-project-decidophobia/world.py\", line 310, in step\n    raise ValueError(\nValueError: [INVALID:STEP] Not a valid step from [4 3] to [4 3] and put barrier at 0, with max steps = 4\n\nExecute Random Walk!\nAn exception raised. The traceback is as follows:\nTraceback (most recent call last):\n  File \"/home/ml/users/ksinha4/mlp/comp424_final_project/submissions/comp424mcgill/final-project-decidophobia/world.py\", line 310, in step\n    raise ValueError(\nValueError: [INVALID:STEP] Not a valid step from [5 4] to [5 4] and put barrier at 0, with max steps = 4\n\nExecute Random Walk!\nAn exception raised. The traceback is as follows:\nTraceback (most recent call last):\n  File \"/home/ml/users/ksinha4/mlp/comp424_final_project/submissions/comp424mcgill/final-project-decidophobia/world.py\", line 310, in step\n    raise ValueError(\nValueError: [INVALID:STEP] Not a valid step from [6 3] to [6 3] and put barrier at 0, with max steps = 4\n\nExecute Random Walk!\n"}, {"student_agent_score": 1, "random_agent_score": 48, "student_agent_time": 0.0031647682189941406, "random_agent_time": 0.0020780563354492188, "board_size": 7, "swap_players": true, "run_out": "An exception raised. The traceback is as follows:\nTraceback (most recent call last):\n  File \"/home/ml/users/ksinha4/mlp/comp424_final_project/submissions/comp424mcgill/final-project-decidophobia/world.py\", line 310, in step\n    raise ValueError(\nValueError: [INVALID:STEP] Not a valid step from [2 3] to [2 3] and put barrier at 0, with max steps = 4\n\nExecute Random Walk!\nAn exception raised. The traceback is as follows:\nTraceback (most recent call last):\n  File \"/home/ml/users/ksinha4/mlp/comp424_final_project/submissions/comp424mcgill/final-project-decidophobia/world.py\", line 310, in step\n    raise ValueError(\nValueError: [INVALID:STEP] Not a valid step from [5 4] to [5 4] and put barrier at 0, with max steps = 4\n\nExecute Random Walk!\nAn exception raised. The traceback is as follows:\nTraceback (most recent call last):\n  File \"/home/ml/users/ksinha4/mlp/comp424_final_project/submissions/comp424mcgill/final-project-decidophobia/world.py\", line 310, in step\n    raise ValueError(\nValueError: [INVALID:STEP] Not a valid step from [6 3] to [6 3] and put barrier at 0, with max steps = 4\n\nExecute Random Walk!\n"}, {"student_agent_score": 1, "random_agent_score": 48, "student_agent_time": 0.0048444271087646484, "random_agent_time": 0.0028350353240966797, "board_size": 7, "swap_players": false, "run_out": "An exception raised. The traceback is as follows:\nTraceback (most recent call last):\n  File \"/home/ml/users/ksinha4/mlp/comp424_final_project/submissions/comp424mcgill/final-project-decidophobia/world.py\", line 310, in step\n    raise ValueError(\nValueError: [INVALID:STEP] Not a valid step from [4 3] to [4 3] and put barrier at 0, with max steps = 4\n\nExecute Random Walk!\nAn exception raised. The traceback is as follows:\nTraceback (most recent call last):\n  File \"/home/ml/users/ksinha4/mlp/comp424_final_project/submissions/comp424mcgill/final-project-decidophobia/world.py\", line 310, in step\n    raise ValueError(\nValueError: [INVALID:STEP] Not a valid step from [4 2] to [4 2] and put barrier at 0, with max steps = 4\n\nExecute Random Walk!\nAn exception raised. The traceback is as follows:\nTraceback (most recent call last):\n  File \"/home/ml/users/ksinha4/mlp/comp424_final_project/submissions/comp424mcgill/final-project-decidophobia/world.py\", line 310, in step\n    raise ValueError(\nValueError: [INVALID:STEP] Not a valid step from [4 3] to [4 3] and put barrier at 0, with max steps = 4\n\nExecute Random Walk!\nAn exception raised. The traceback is as follows:\nTraceback (most recent call last):\n  File \"/home/ml/users/ksinha4/mlp/comp424_final_project/submissions/comp424mcgill/final-project-decidophobia/world.py\", line 310, in step\n    raise ValueError(\nValueError: [INVALID:STEP] Not a valid step from [5 4] to [5 4] and put barrier at 0, with max steps = 4\n\nExecute Random Walk!\nAn exception raised. The traceback is as follows:\nTraceback (most recent call last):\n  File \"/home/ml/users/ksinha4/mlp/comp424_final_project/submissions/comp424mcgill/final-project-decidophobia/world.py\", line 310, in step\n    raise ValueError(\nValueError: [INVALID:STEP] Not a valid step from [6 3] to [6 3] and put barrier at 0, with max steps = 4\n\nExecute Random Walk!\n"}, {"student_agent_score": 1, "random_agent_score": 48, "student_agent_time": 0.002941608428955078, "random_agent_time": 0.002534151077270508, "board_size": 7, "swap_players": true, "run_out": "An exception raised. The traceback is as follows:\nTraceback (most recent call last):\n  File \"/home/ml/users/ksinha4/mlp/comp424_final_project/submissions/comp424mcgill/final-project-decidophobia/world.py\", line 310, in step\n    raise ValueError(\nValueError: [INVALID:STEP] Not a valid step from [2 3] to [2 3] and put barrier at 0, with max steps = 4\n\nExecute Random Walk!\nAn exception raised. The traceback is as follows:\nTraceback (most recent call last):\n  File \"/home/ml/users/ksinha4/mlp/comp424_final_project/submissions/comp424mcgill/final-project-decidophobia/world.py\", line 310, in step\n    raise ValueError(\nValueError: [INVALID:STEP] Not a valid step from [5 4] to [5 4] and put barrier at 0, with max steps = 4\n\nExecute Random Walk!\nAn exception raised. The traceback is as follows:\nTraceback (most recent call last):\n  File \"/home/ml/users/ksinha4/mlp/comp424_final_project/submissions/comp424mcgill/final-project-decidophobia/world.py\", line 310, in step\n    raise ValueError(\nValueError: [INVALID:STEP] Not a valid step from [6 3] to [6 3] and put barrier at 0, with max steps = 4\n\nExecute Random Walk!\n"}, {"student_agent_score": 1, "random_agent_score": 48, "student_agent_time": 0.005081892013549805, "random_agent_time": 0.0028285980224609375, "board_size": 7, "swap_players": false, "run_out": "An exception raised. The traceback is as follows:\nTraceback (most recent call last):\n  File \"/home/ml/users/ksinha4/mlp/comp424_final_project/submissions/comp424mcgill/final-project-decidophobia/world.py\", line 310, in step\n    raise ValueError(\nValueError: [INVALID:STEP] Not a valid step from [4 3] to [4 3] and put barrier at 0, with max steps = 4\n\nExecute Random Walk!\nAn exception raised. The traceback is as follows:\nTraceback (most recent call last):\n  File \"/home/ml/users/ksinha4/mlp/comp424_final_project/submissions/comp424mcgill/final-project-decidophobia/world.py\", line 310, in step\n    raise ValueError(\nValueError: [INVALID:STEP] Not a valid step from [4 2] to [4 2] and put barrier at 0, with max steps = 4\n\nExecute Random Walk!\nAn exception raised. The traceback is as follows:\nTraceback (most recent call last):\n  File \"/home/ml/users/ksinha4/mlp/comp424_final_project/submissions/comp424mcgill/final-project-decidophobia/world.py\", line 310, in step\n    raise ValueError(\nValueError: [INVALID:STEP] Not a valid step from [4 3] to [4 3] and put barrier at 0, with max steps = 4\n\nExecute Random Walk!\nAn exception raised. The traceback is as follows:\nTraceback (most recent call last):\n  File \"/home/ml/users/ksinha4/mlp/comp424_final_project/submissions/comp424mcgill/final-project-decidophobia/world.py\", line 310, in step\n    raise ValueError(\nValueError: [INVALID:STEP] Not a valid step from [5 4] to [5 4] and put barrier at 0, with max steps = 4\n\nExecute Random Walk!\nAn exception raised. The traceback is as follows:\nTraceback (most recent call last):\n  File \"/home/ml/users/ksinha4/mlp/comp424_final_project/submissions/comp424mcgill/final-project-decidophobia/world.py\", line 310, in step\n    raise ValueError(\nValueError: [INVALID:STEP] Not a valid step from [6 3] to [6 3] and put barrier at 0, with max steps = 4\n\nExecute Random Walk!\n"}, {"student_agent_score": 2, "random_agent_score": 98, "student_agent_time": 0.006202220916748047, "random_agent_time": 0.006174325942993164, "board_size": 10, "swap_players": false, "run_out": "An exception raised. The traceback is as follows:\nTraceback (most recent call last):\n  File \"/home/ml/users/ksinha4/mlp/comp424_final_project/submissions/comp424mcgill/final-project-decidophobia/world.py\", line 310, in step\n    raise ValueError(\nValueError: [INVALID:STEP] Not a valid step from [7 5] to [7 5] and put barrier at 0, with max steps = 5\n\nExecute Random Walk!\nAn exception raised. The traceback is as follows:\nTraceback (most recent call last):\n  File \"/home/ml/users/ksinha4/mlp/comp424_final_project/submissions/comp424mcgill/final-project-decidophobia/world.py\", line 310, in step\n    raise ValueError(\nValueError: [INVALID:STEP] Not a valid step from [6 6] to [6 6] and put barrier at 0, with max steps = 5\n\nExecute Random Walk!\nAn exception raised. The traceback is as follows:\nTraceback (most recent call last):\n  File \"/home/ml/users/ksinha4/mlp/comp424_final_project/submissions/comp424mcgill/final-project-decidophobia/world.py\", line 310, in step\n    raise ValueError(\nValueError: [INVALID:STEP] Not a valid step from [7 8] to [7 8] and put barrier at 0, with max steps = 5\n\nExecute Random Walk!\nAn exception raised. The traceback is as follows:\nTraceback (most recent call last):\n  File \"/home/ml/users/ksinha4/mlp/comp424_final_project/submissions/comp424mcgill/final-project-decidophobia/world.py\", line 310, in step\n    raise ValueError(\nValueError: [INVALID:STEP] Not a valid step from [7 8] to [7 8] and put barrier at 0, with max steps = 5\n\nExecute Random Walk!\n"}, {"student_agent_score": 117, "random_agent_score": 1, "student_agent_time": 0.009167909622192383, "random_agent_time": 0.0073091983795166016, "board_size": 11, "swap_players": false, "run_out": "An exception raised. The traceback is as follows:\nTraceback (most recent call last):\n  File \"/home/ml/users/ksinha4/mlp/comp424_final_project/submissions/comp424mcgill/final-project-decidophobia/world.py\", line 310, in step\n    raise ValueError(\nValueError: [INVALID:STEP] Not a valid step from [1 7] to [1 7] and put barrier at 0, with max steps = 6\n\nExecute Random Walk!\nAn exception raised. The traceback is as follows:\nTraceback (most recent call last):\n  File \"/home/ml/users/ksinha4/mlp/comp424_final_project/submissions/comp424mcgill/final-project-decidophobia/world.py\", line 310, in step\n    raise ValueError(\nValueError: [INVALID:STEP] Not a valid step from [1 8] to [1 8] and put barrier at 0, with max steps = 6\n\nExecute Random Walk!\nAn exception raised. The traceback is as follows:\nTraceback (most recent call last):\n  File \"/home/ml/users/ksinha4/mlp/comp424_final_project/submissions/comp424mcgill/final-project-decidophobia/world.py\", line 310, in step\n    raise ValueError(\nValueError: [INVALID:STEP] Not a valid step from [1 6] to [1 6] and put barrier at 0, with max steps = 6\n\nExecute Random Walk!\nAn exception raised. The traceback is as follows:\nTraceback (most recent call last):\n  File \"/home/ml/users/ksinha4/mlp/comp424_final_project/submissions/comp424mcgill/final-project-decidophobia/world.py\", line 310, in step\n    raise ValueError(\nValueError: [INVALID:STEP] Not a valid step from [3 3] to [3 3] and put barrier at 0, with max steps = 6\n\nExecute Random Walk!\nAn exception raised. The traceback is as follows:\nTraceback (most recent call last):\n  File \"/home/ml/users/ksinha4/mlp/comp424_final_project/submissions/comp424mcgill/final-project-decidophobia/world.py\", line 310, in step\n    raise ValueError(\nValueError: [INVALID:STEP] Not a valid step from [3 4] to [3 4] and put barrier at 0, with max steps = 6\n\nExecute Random Walk!\nAn exception raised. The traceback is as follows:\nTraceback (most recent call last):\n  File \"/home/ml/users/ksinha4/mlp/comp424_final_project/submissions/comp424mcgill/final-project-decidophobia/world.py\", line 310, in step\n    raise ValueError(\nValueError: [INVALID:STEP] Not a valid step from [3 4] to [3 4] and put barrier at 0, with max steps = 6\n\nExecute Random Walk!\nAn exception raised. The traceback is as follows:\nTraceback (most recent call last):\n  File \"/home/ml/users/ksinha4/mlp/comp424_final_project/submissions/comp424mcgill/final-project-decidophobia/world.py\", line 310, in step\n    raise ValueError(\nValueError: [INVALID:STEP] Not a valid step from [4 4] to [4 4] and put barrier at 0, with max steps = 6\n\nExecute Random Walk!\nAn exception raised. The traceback is as follows:\nTraceback (most recent call last):\n  File \"/home/ml/users/ksinha4/mlp/comp424_final_project/submissions/comp424mcgill/final-project-decidophobia/world.py\", line 310, in step\n    raise ValueError(\nValueError: [INVALID:STEP] Not a valid step from [4 4] to [4 4] and put barrier at 0, with max steps = 6\n\nExecute Random Walk!\n"}, {"student_agent_score": 1, "random_agent_score": 48, "student_agent_time": 0.0029518604278564453, "random_agent_time": 0.003147602081298828, "board_size": 7, "swap_players": true, "run_out": "An exception raised. The traceback is as follows:\nTraceback (most recent call last):\n  File \"/home/ml/users/ksinha4/mlp/comp424_final_project/submissions/comp424mcgill/final-project-decidophobia/world.py\", line 310, in step\n    raise ValueError(\nValueError: [INVALID:STEP] Not a valid step from [2 3] to [2 3] and put barrier at 0, with max steps = 4\n\nExecute Random Walk!\nAn exception raised. The traceback is as follows:\nTraceback (most recent call last):\n  File \"/home/ml/users/ksinha4/mlp/comp424_final_project/submissions/comp424mcgill/final-project-decidophobia/world.py\", line 310, in step\n    raise ValueError(\nValueError: [INVALID:STEP] Not a valid step from [5 4] to [5 4] and put barrier at 0, with max steps = 4\n\nExecute Random Walk!\nAn exception raised. The traceback is as follows:\nTraceback (most recent call last):\n  File \"/home/ml/users/ksinha4/mlp/comp424_final_project/submissions/comp424mcgill/final-project-decidophobia/world.py\", line 310, in step\n    raise ValueError(\nValueError: [INVALID:STEP] Not a valid step from [6 3] to [6 3] and put barrier at 0, with max steps = 4\n\nExecute Random Walk!\n"}, {"student_agent_score": 80, "random_agent_score": 1, "student_agent_time": 0.004141569137573242, "random_agent_time": 0.0052280426025390625, "board_size": 9, "swap_players": true, "run_out": "An exception raised. The traceback is as follows:\nTraceback (most recent call last):\n  File \"/home/ml/users/ksinha4/mlp/comp424_final_project/submissions/comp424mcgill/final-project-decidophobia/world.py\", line 310, in step\n    raise ValueError(\nValueError: [INVALID:STEP] Not a valid step from [3 4] to [3 4] and put barrier at 0, with max steps = 5\n\nExecute Random Walk!\nAn exception raised. The traceback is as follows:\nTraceback (most recent call last):\n  File \"/home/ml/users/ksinha4/mlp/comp424_final_project/submissions/comp424mcgill/final-project-decidophobia/world.py\", line 310, in step\n    raise ValueError(\nValueError: [INVALID:STEP] Not a valid step from [3 5] to [3 5] and put barrier at 0, with max steps = 5\n\nExecute Random Walk!\nAn exception raised. The traceback is as follows:\nTraceback (most recent call last):\n  File \"/home/ml/users/ksinha4/mlp/comp424_final_project/submissions/comp424mcgill/final-project-decidophobia/world.py\", line 310, in step\n    raise ValueError(\nValueError: [INVALID:STEP] Not a valid step from [3 4] to [3 4] and put barrier at 0, with max steps = 5\n\nExecute Random Walk!\nAn exception raised. The traceback is as follows:\nTraceback (most recent call last):\n  File \"/home/ml/users/ksinha4/mlp/comp424_final_project/submissions/comp424mcgill/final-project-decidophobia/world.py\", line 310, in step\n    raise ValueError(\nValueError: [INVALID:STEP] Not a valid step from [5 4] to [5 4] and put barrier at 0, with max steps = 5\n\nExecute Random Walk!\nAn exception raised. The traceback is as follows:\nTraceback (most recent call last):\n  File \"/home/ml/users/ksinha4/mlp/comp424_final_project/submissions/comp424mcgill/final-project-decidophobia/world.py\", line 310, in step\n    raise ValueError(\nValueError: [INVALID:STEP] Not a valid step from [5 5] to [5 5] and put barrier at 0, with max steps = 5\n\nExecute Random Walk!\n"}, {"student_agent_score": 1, "random_agent_score": 48, "student_agent_time": 0.0027036666870117188, "random_agent_time": 0.0030775070190429688, "board_size": 7, "swap_players": true, "run_out": "An exception raised. The traceback is as follows:\nTraceback (most recent call last):\n  File \"/home/ml/users/ksinha4/mlp/comp424_final_project/submissions/comp424mcgill/final-project-decidophobia/world.py\", line 310, in step\n    raise ValueError(\nValueError: [INVALID:STEP] Not a valid step from [2 3] to [2 3] and put barrier at 0, with max steps = 4\n\nExecute Random Walk!\nAn exception raised. The traceback is as follows:\nTraceback (most recent call last):\n  File \"/home/ml/users/ksinha4/mlp/comp424_final_project/submissions/comp424mcgill/final-project-decidophobia/world.py\", line 310, in step\n    raise ValueError(\nValueError: [INVALID:STEP] Not a valid step from [5 4] to [5 4] and put barrier at 0, with max steps = 4\n\nExecute Random Walk!\nAn exception raised. The traceback is as follows:\nTraceback (most recent call last):\n  File \"/home/ml/users/ksinha4/mlp/comp424_final_project/submissions/comp424mcgill/final-project-decidophobia/world.py\", line 310, in step\n    raise ValueError(\nValueError: [INVALID:STEP] Not a valid step from [6 3] to [6 3] and put barrier at 0, with max steps = 4\n\nExecute Random Walk!\n"}, {"student_agent_score": 1, "random_agent_score": 48, "student_agent_time": 0.0046422481536865234, "random_agent_time": 0.0020067691802978516, "board_size": 7, "swap_players": false, "run_out": "An exception raised. The traceback is as follows:\nTraceback (most recent call last):\n  File \"/home/ml/users/ksinha4/mlp/comp424_final_project/submissions/comp424mcgill/final-project-decidophobia/world.py\", line 310, in step\n    raise ValueError(\nValueError: [INVALID:STEP] Not a valid step from [4 3] to [4 3] and put barrier at 0, with max steps = 4\n\nExecute Random Walk!\nAn exception raised. The traceback is as follows:\nTraceback (most recent call last):\n  File \"/home/ml/users/ksinha4/mlp/comp424_final_project/submissions/comp424mcgill/final-project-decidophobia/world.py\", line 310, in step\n    raise ValueError(\nValueError: [INVALID:STEP] Not a valid step from [4 2] to [4 2] and put barrier at 0, with max steps = 4\n\nExecute Random Walk!\nAn exception raised. The traceback is as follows:\nTraceback (most recent call last):\n  File \"/home/ml/users/ksinha4/mlp/comp424_final_project/submissions/comp424mcgill/final-project-decidophobia/world.py\", line 310, in step\n    raise ValueError(\nValueError: [INVALID:STEP] Not a valid step from [4 3] to [4 3] and put barrier at 0, with max steps = 4\n\nExecute Random Walk!\nAn exception raised. The traceback is as follows:\nTraceback (most recent call last):\n  File \"/home/ml/users/ksinha4/mlp/comp424_final_project/submissions/comp424mcgill/final-project-decidophobia/world.py\", line 310, in step\n    raise ValueError(\nValueError: [INVALID:STEP] Not a valid step from [5 4] to [5 4] and put barrier at 0, with max steps = 4\n\nExecute Random Walk!\nAn exception raised. The traceback is as follows:\nTraceback (most recent call last):\n  File \"/home/ml/users/ksinha4/mlp/comp424_final_project/submissions/comp424mcgill/final-project-decidophobia/world.py\", line 310, in step\n    raise ValueError(\nValueError: [INVALID:STEP] Not a valid step from [6 3] to [6 3] and put barrier at 0, with max steps = 4\n\nExecute Random Walk!\n"}, {"student_agent_score": 1, "random_agent_score": 63, "student_agent_time": 0.0036847591400146484, "random_agent_time": 0.003092050552368164, "board_size": 8, "swap_players": false, "run_out": "An exception raised. The traceback is as follows:\nTraceback (most recent call last):\n  File \"/home/ml/users/ksinha4/mlp/comp424_final_project/submissions/comp424mcgill/final-project-decidophobia/world.py\", line 310, in step\n    raise ValueError(\nValueError: [INVALID:STEP] Not a valid step from [2 2] to [2 2] and put barrier at 0, with max steps = 4\n\nExecute Random Walk!\nAn exception raised. The traceback is as follows:\nTraceback (most recent call last):\n  File \"/home/ml/users/ksinha4/mlp/comp424_final_project/submissions/comp424mcgill/final-project-decidophobia/world.py\", line 310, in step\n    raise ValueError(\nValueError: [INVALID:STEP] Not a valid step from [3 1] to [3 1] and put barrier at 0, with max steps = 4\n\nExecute Random Walk!\nAn exception raised. The traceback is as follows:\nTraceback (most recent call last):\n  File \"/home/ml/users/ksinha4/mlp/comp424_final_project/submissions/comp424mcgill/final-project-decidophobia/world.py\", line 310, in step\n    raise ValueError(\nValueError: [INVALID:STEP] Not a valid step from [3 0] to [3 0] and put barrier at 0, with max steps = 4\n\nExecute Random Walk!\nAn exception raised. The traceback is as follows:\nTraceback (most recent call last):\n  File \"/home/ml/users/ksinha4/mlp/comp424_final_project/submissions/comp424mcgill/final-project-decidophobia/world.py\", line 310, in step\n    raise ValueError(\nValueError: [INVALID:STEP] Not a valid step from [6 1] to [6 1] and put barrier at 0, with max steps = 4\n\nExecute Random Walk!\n"}, {"student_agent_score": 1, "random_agent_score": 48, "student_agent_time": 0.0023987293243408203, "random_agent_time": 0.0026254653930664062, "board_size": 7, "swap_players": true, "run_out": "An exception raised. The traceback is as follows:\nTraceback (most recent call last):\n  File \"/home/ml/users/ksinha4/mlp/comp424_final_project/submissions/comp424mcgill/final-project-decidophobia/world.py\", line 310, in step\n    raise ValueError(\nValueError: [INVALID:STEP] Not a valid step from [2 3] to [2 3] and put barrier at 0, with max steps = 4\n\nExecute Random Walk!\nAn exception raised. The traceback is as follows:\nTraceback (most recent call last):\n  File \"/home/ml/users/ksinha4/mlp/comp424_final_project/submissions/comp424mcgill/final-project-decidophobia/world.py\", line 310, in step\n    raise ValueError(\nValueError: [INVALID:STEP] Not a valid step from [5 4] to [5 4] and put barrier at 0, with max steps = 4\n\nExecute Random Walk!\nAn exception raised. The traceback is as follows:\nTraceback (most recent call last):\n  File \"/home/ml/users/ksinha4/mlp/comp424_final_project/submissions/comp424mcgill/final-project-decidophobia/world.py\", line 310, in step\n    raise ValueError(\nValueError: [INVALID:STEP] Not a valid step from [6 3] to [6 3] and put barrier at 0, with max steps = 4\n\nExecute Random Walk!\n"}, {"student_agent_score": 1, "random_agent_score": 48, "student_agent_time": 0.003330230712890625, "random_agent_time": 0.0017330646514892578, "board_size": 7, "swap_players": false, "run_out": "An exception raised. The traceback is as follows:\nTraceback (most recent call last):\n  File \"/home/ml/users/ksinha4/mlp/comp424_final_project/submissions/comp424mcgill/final-project-decidophobia/world.py\", line 310, in step\n    raise ValueError(\nValueError: [INVALID:STEP] Not a valid step from [4 3] to [4 3] and put barrier at 0, with max steps = 4\n\nExecute Random Walk!\nAn exception raised. The traceback is as follows:\nTraceback (most recent call last):\n  File \"/home/ml/users/ksinha4/mlp/comp424_final_project/submissions/comp424mcgill/final-project-decidophobia/world.py\", line 310, in step\n    raise ValueError(\nValueError: [INVALID:STEP] Not a valid step from [4 2] to [4 2] and put barrier at 0, with max steps = 4\n\nExecute Random Walk!\nAn exception raised. The traceback is as follows:\nTraceback (most recent call last):\n  File \"/home/ml/users/ksinha4/mlp/comp424_final_project/submissions/comp424mcgill/final-project-decidophobia/world.py\", line 310, in step\n    raise ValueError(\nValueError: [INVALID:STEP] Not a valid step from [4 3] to [4 3] and put barrier at 0, with max steps = 4\n\nExecute Random Walk!\nAn exception raised. The traceback is as follows:\nTraceback (most recent call last):\n  File \"/home/ml/users/ksinha4/mlp/comp424_final_project/submissions/comp424mcgill/final-project-decidophobia/world.py\", line 310, in step\n    raise ValueError(\nValueError: [INVALID:STEP] Not a valid step from [5 4] to [5 4] and put barrier at 0, with max steps = 4\n\nExecute Random Walk!\nAn exception raised. The traceback is as follows:\nTraceback (most recent call last):\n  File \"/home/ml/users/ksinha4/mlp/comp424_final_project/submissions/comp424mcgill/final-project-decidophobia/world.py\", line 310, in step\n    raise ValueError(\nValueError: [INVALID:STEP] Not a valid step from [6 3] to [6 3] and put barrier at 0, with max steps = 4\n\nExecute Random Walk!\n"}, {"student_agent_score": 1, "random_agent_score": 48, "student_agent_time": 0.004011869430541992, "random_agent_time": 0.0017697811126708984, "board_size": 7, "swap_players": false, "run_out": "An exception raised. The traceback is as follows:\nTraceback (most recent call last):\n  File \"/home/ml/users/ksinha4/mlp/comp424_final_project/submissions/comp424mcgill/final-project-decidophobia/world.py\", line 310, in step\n    raise ValueError(\nValueError: [INVALID:STEP] Not a valid step from [4 3] to [4 3] and put barrier at 0, with max steps = 4\n\nExecute Random Walk!\nAn exception raised. The traceback is as follows:\nTraceback (most recent call last):\n  File \"/home/ml/users/ksinha4/mlp/comp424_final_project/submissions/comp424mcgill/final-project-decidophobia/world.py\", line 310, in step\n    raise ValueError(\nValueError: [INVALID:STEP] Not a valid step from [4 2] to [4 2] and put barrier at 0, with max steps = 4\n\nExecute Random Walk!\nAn exception raised. The traceback is as follows:\nTraceback (most recent call last):\n  File \"/home/ml/users/ksinha4/mlp/comp424_final_project/submissions/comp424mcgill/final-project-decidophobia/world.py\", line 310, in step\n    raise ValueError(\nValueError: [INVALID:STEP] Not a valid step from [4 3] to [4 3] and put barrier at 0, with max steps = 4\n\nExecute Random Walk!\nAn exception raised. The traceback is as follows:\nTraceback (most recent call last):\n  File \"/home/ml/users/ksinha4/mlp/comp424_final_project/submissions/comp424mcgill/final-project-decidophobia/world.py\", line 310, in step\n    raise ValueError(\nValueError: [INVALID:STEP] Not a valid step from [5 4] to [5 4] and put barrier at 0, with max steps = 4\n\nExecute Random Walk!\nAn exception raised. The traceback is as follows:\nTraceback (most recent call last):\n  File \"/home/ml/users/ksinha4/mlp/comp424_final_project/submissions/comp424mcgill/final-project-decidophobia/world.py\", line 310, in step\n    raise ValueError(\nValueError: [INVALID:STEP] Not a valid step from [6 3] to [6 3] and put barrier at 0, with max steps = 4\n\nExecute Random Walk!\n"}]}